Workbook
Name YearList: Lists!$A$1:$A$15
Name MonthList: Lists!$C$1:$C$12
Name ChannelList: OFFSET(Lists!$E$1,0,0,COUNTIF(Lists!$E$1:$E$40,"?*"),1)

Sheet Dashboard
B2: SCB Video Library
B3: =IF(Settings!$C$5="","","Last updated "&TEXT(Settings!$C$5,"d mmm yyyy h:mm AM/PM")&" · "&TODAY()-INT(Settings!$C$5)&" day(s) ago")
B4: =HYPERLINK("#Library!A1","Library") | C4: =HYPERLINK("#Queue!A1","Queue") | D4: =HYPERLINK("#Calendar!A1","Calendar") | E4: =HYPERLINK("#History!A1","History") | F4: =HYPERLINK("#Stats!A1","Stats") | G4: =HYPERLINK("#Channels!A1","Channels") | H4: =HYPERLINK("#Settings!A1","Settings")
B6: TOTAL VIDEOS | D6: WATCHED | F6: BACKLOG | H6: % WATCHED | J6: HOURS WATCHED | L6: HOURS REMAINING
B7: =Stats!C14 | D7: =Stats!D14 | F7: =Stats!E14+Stats!F14 | H7: =Stats!H14 | J7: =Stats!J14 | L7: =Stats!K14
B8: ="across "&6&" channels" | D8: ="of "&TEXT(Stats!C14-Stats!G14,"#,##0")&" tracked" | F8: =TEXT(Stats!E14,"#,##0")&" watch-later" | H8: =TEXT(Stats!L14,"0.0%")&" of runtime" | J8: ="of "&TEXT(Stats!I14,"#,##0")&" h total" | L8: ="≈ "&TEXT(Stats!K14/24,"#,##0")&" days of video"
B10: By channel
B11: Channel | E11: Videos | F11: Watched | G11: Backlog | H11: % Watched | I11: Hours left | J11: Latest upload | L11: Days since
B12: =Stats!B8 | E12: =Stats!C8 | F12: =Stats!D8 | G12: =Stats!E8+Stats!F8 | H12: =Stats!H8 | I12: =Stats!K8 | J12: =Stats!D20 | L12: =IF(J12="","",TODAY()-J12)
B13: =Stats!B9 | E13: =Stats!C9 | F13: =Stats!D9 | G13: =Stats!E9+Stats!F9 | H13: =Stats!H9 | I13: =Stats!K9 | J13: =Stats!D21 | L13: =IF(J13="","",TODAY()-J13)
B14: =Stats!B10 | E14: =Stats!C10 | F14: =Stats!D10 | G14: =Stats!E10+Stats!F10 | H14: =Stats!H10 | I14: =Stats!K10 | J14: =Stats!D22 | L14: =IF(J14="","",TODAY()-J14)
B15: =Stats!B11 | E15: =Stats!C11 | F15: =Stats!D11 | G15: =Stats!E11+Stats!F11 | H15: =Stats!H11 | I15: =Stats!K11 | J15: =Stats!D23 | L15: =IF(J15="","",TODAY()-J15)
B16: =Stats!B12 | E16: =Stats!C12 | F16: =Stats!D12 | G16: =Stats!E12+Stats!F12 | H16: =Stats!H12 | I16: =Stats!K12 | J16: =Stats!D24 | L16: =IF(J16="","",TODAY()-J16)
B17: =Stats!B13 | E17: =Stats!C13 | F17: =Stats!D13 | G17: =Stats!E13+Stats!F13 | H17: =Stats!H13 | I17: =Stats!K13 | J17: =Stats!D25 | L17: =IF(J17="","",TODAY()-J17)
B18: All channels | E18: =Stats!C14 | F18: =Stats!D14 | G18: =Stats!E14+Stats!F14 | H18: =Stats!H14 | I18: =Stats!K14
B36: Up next - oldest unwatched video in each channel
B37: Channel | E37: Video | L37: Length | M37: Published
B38: =Channels!$C$6 | E38: =IF($O38="","All caught up ✓",IF(INDEX(tblVideos[Video ID],$O38)="",INDEX(tblVideos[Title],$O38),HYPERLINK("https://www.youtube.com/watch?v="&INDEX(tblVideos[Video ID],$O38),INDEX(tblVideos[Title],$O38)))) | L38: =IF($O38="","",INDEX(tblVideos[Length],$O38)) | M38: =IF($O38="","",INDEX(tblVideos[Day],$O38)) | O38: =IF(_xlfn.MINIFS(tblVideos[Seq],tblVideos[Channel ID],Channels!$E$6,tblVideos[Status],"Unwatched")=0,"",MATCH(_xlfn.MINIFS(tblVideos[Seq],tblVideos[Channel ID],Channels!$E$6,tblVideos[Status],"Unwatched"),tblVideos[Seq],0))
B39: =Channels!$C$7 | E39: =IF($O39="","All caught up ✓",IF(INDEX(tblVideos[Video ID],$O39)="",INDEX(tblVideos[Title],$O39),HYPERLINK("https://www.youtube.com/watch?v="&INDEX(tblVideos[Video ID],$O39),INDEX(tblVideos[Title],$O39)))) | L39: =IF($O39="","",INDEX(tblVideos[Length],$O39)) | M39: =IF($O39="","",INDEX(tblVideos[Day],$O39)) | O39: =IF(_xlfn.MINIFS(tblVideos[Seq],tblVideos[Channel ID],Channels!$E$7,tblVideos[Status],"Unwatched")=0,"",MATCH(_xlfn.MINIFS(tblVideos[Seq],tblVideos[Channel ID],Channels!$E$7,tblVideos[Status],"Unwatched"),tblVideos[Seq],0))
B40: =Channels!$C$8 | E40: =IF($O40="","All caught up ✓",IF(INDEX(tblVideos[Video ID],$O40)="",INDEX(tblVideos[Title],$O40),HYPERLINK("https://www.youtube.com/watch?v="&INDEX(tblVideos[Video ID],$O40),INDEX(tblVideos[Title],$O40)))) | L40: =IF($O40="","",INDEX(tblVideos[Length],$O40)) | M40: =IF($O40="","",INDEX(tblVideos[Day],$O40)) | O40: =IF(_xlfn.MINIFS(tblVideos[Seq],tblVideos[Channel ID],Channels!$E$8,tblVideos[Status],"Unwatched")=0,"",MATCH(_xlfn.MINIFS(tblVideos[Seq],tblVideos[Channel ID],Channels!$E$8,tblVideos[Status],"Unwatched"),tblVideos[Seq],0))
B41: =Channels!$C$9 | E41: =IF($O41="","All caught up ✓",IF(INDEX(tblVideos[Video ID],$O41)="",INDEX(tblVideos[Title],$O41),HYPERLINK("https://www.youtube.com/watch?v="&INDEX(tblVideos[Video ID],$O41),INDEX(tblVideos[Title],$O41)))) | L41: =IF($O41="","",INDEX(tblVideos[Length],$O41)) | M41: =IF($O41="","",INDEX(tblVideos[Day],$O41)) | O41: =IF(_xlfn.MINIFS(tblVideos[Seq],tblVideos[Channel ID],Channels!$E$9,tblVideos[Status],"Unwatched")=0,"",MATCH(_xlfn.MINIFS(tblVideos[Seq],tblVideos[Channel ID],Channels!$E$9,tblVideos[Status],"Unwatched"),tblVideos[Seq],0))
B42: =Channels!$C$10 | E42: =IF($O42="","All caught up ✓",IF(INDEX(tblVideos[Video ID],$O42)="",INDEX(tblVideos[Title],$O42),HYPERLINK("https://www.youtube.com/watch?v="&INDEX(tblVideos[Video ID],$O42),INDEX(tblVideos[Title],$O42)))) | L42: =IF($O42="","",INDEX(tblVideos[Length],$O42)) | M42: =IF($O42="","",INDEX(tblVideos[Day],$O42)) | O42: =IF(_xlfn.MINIFS(tblVideos[Seq],tblVideos[Channel ID],Channels!$E$10,tblVideos[Status],"Unwatched")=0,"",MATCH(_xlfn.MINIFS(tblVideos[Seq],tblVideos[Channel ID],Channels!$E$10,tblVideos[Status],"Unwatched"),tblVideos[Seq],0))
B43: =Channels!$C$11 | E43: =IF($O43="","All caught up ✓",IF(INDEX(tblVideos[Video ID],$O43)="",INDEX(tblVideos[Title],$O43),HYPERLINK("https://www.youtube.com/watch?v="&INDEX(tblVideos[Video ID],$O43),INDEX(tblVideos[Title],$O43)))) | L43: =IF($O43="","",INDEX(tblVideos[Length],$O43)) | M43: =IF($O43="","",INDEX(tblVideos[Day],$O43)) | O43: =IF(_xlfn.MINIFS(tblVideos[Seq],tblVideos[Channel ID],Channels!$E$11,tblVideos[Status],"Unwatched")=0,"",MATCH(_xlfn.MINIFS(tblVideos[Seq],tblVideos[Channel ID],Channels!$E$11,tblVideos[Status],"Unwatched"),tblVideos[Seq],0))
B46: Newest uploads
B47: Published | D47: Channel | F47: Title | L47: Length | M47: Status
B48: =IF($O48="","",INDEX(tblVideos[Day],$O48)) | D48: =IF($O48="","",INDEX(tblVideos[Channel],$O48)) | F48: =IF($O48="","",IF(INDEX(tblVideos[Video ID],$O48)="",INDEX(tblVideos[Title],$O48),HYPERLINK("https://www.youtube.com/watch?v="&INDEX(tblVideos[Video ID],$O48),INDEX(tblVideos[Title],$O48)))) | L48: =IF($O48="","",INDEX(tblVideos[Length],$O48)) | M48: =IF($O48="","",INDEX(tblVideos[Status],$O48)) | O48: =IFERROR(MATCH(MAX(tblVideos[Seq])-0,tblVideos[Seq],0),"")
B49: =IF($O49="","",INDEX(tblVideos[Day],$O49)) | D49: =IF($O49="","",INDEX(tblVideos[Channel],$O49)) | F49: =IF($O49="","",IF(INDEX(tblVideos[Video ID],$O49)="",INDEX(tblVideos[Title],$O49),HYPERLINK("https://www.youtube.com/watch?v="&INDEX(tblVideos[Video ID],$O49),INDEX(tblVideos[Title],$O49)))) | L49: =IF($O49="","",INDEX(tblVideos[Length],$O49)) | M49: =IF($O49="","",INDEX(tblVideos[Status],$O49)) | O49: =IFERROR(MATCH(MAX(tblVideos[Seq])-1,tblVideos[Seq],0),"")
B50: =IF($O50="","",INDEX(tblVideos[Day],$O50)) | D50: =IF($O50="","",INDEX(tblVideos[Channel],$O50)) | F50: =IF($O50="","",IF(INDEX(tblVideos[Video ID],$O50)="",INDEX(tblVideos[Title],$O50),HYPERLINK("https://www.youtube.com/watch?v="&INDEX(tblVideos[Video ID],$O50),INDEX(tblVideos[Title],$O50)))) | L50: =IF($O50="","",INDEX(tblVideos[Length],$O50)) | M50: =IF($O50="","",INDEX(tblVideos[Status],$O50)) | O50: =IFERROR(MATCH(MAX(tblVideos[Seq])-2,tblVideos[Seq],0),"")
B51: =IF($O51="","",INDEX(tblVideos[Day],$O51)) | D51: =IF($O51="","",INDEX(tblVideos[Channel],$O51)) | F51: =IF($O51="","",IF(INDEX(tblVideos[Video ID],$O51)="",INDEX(tblVideos[Title],$O51),HYPERLINK("https://www.youtube.com/watch?v="&INDEX(tblVideos[Video ID],$O51),INDEX(tblVideos[Title],$O51)))) | L51: =IF($O51="","",INDEX(tblVideos[Length],$O51)) | M51: =IF($O51="","",INDEX(tblVideos[Status],$O51)) | O51: =IFERROR(MATCH(MAX(tblVideos[Seq])-3,tblVideos[Seq],0),"")
B52: =IF($O52="","",INDEX(tblVideos[Day],$O52)) | D52: =IF($O52="","",INDEX(tblVideos[Channel],$O52)) | F52: =IF($O52="","",IF(INDEX(tblVideos[Video ID],$O52)="",INDEX(tblVideos[Title],$O52),HYPERLINK("https://www.youtube.com/watch?v="&INDEX(tblVideos[Video ID],$O52),INDEX(tblVideos[Title],$O52)))) | L52: =IF($O52="","",INDEX(tblVideos[Length],$O52)) | M52: =IF($O52="","",INDEX(tblVideos[Status],$O52)) | O52: =IFERROR(MATCH(MAX(tblVideos[Seq])-4,tblVideos[Seq],0),"")
B53: =IF($O53="","",INDEX(tblVideos[Day],$O53)) | D53: =IF($O53="","",INDEX(tblVideos[Channel],$O53)) | F53: =IF($O53="","",IF(INDEX(tblVideos[Video ID],$O53)="",INDEX(tblVideos[Title],$O53),HYPERLINK("https://www.youtube.com/watch?v="&INDEX(tblVideos[Video ID],$O53),INDEX(tblVideos[Title],$O53)))) | L53: =IF($O53="","",INDEX(tblVideos[Length],$O53)) | M53: =IF($O53="","",INDEX(tblVideos[Status],$O53)) | O53: =IFERROR(MATCH(MAX(tblVideos[Seq])-5,tblVideos[Seq],0),"")
B54: =IF($O54="","",INDEX(tblVideos[Day],$O54)) | D54: =IF($O54="","",INDEX(tblVideos[Channel],$O54)) | F54: =IF($O54="","",IF(INDEX(tblVideos[Video ID],$O54)="",INDEX(tblVideos[Title],$O54),HYPERLINK("https://www.youtube.com/watch?v="&INDEX(tblVideos[Video ID],$O54),INDEX(tblVideos[Title],$O54)))) | L54: =IF($O54="","",INDEX(tblVideos[Length],$O54)) | M54: =IF($O54="","",INDEX(tblVideos[Status],$O54)) | O54: =IFERROR(MATCH(MAX(tblVideos[Seq])-6,tblVideos[Seq],0),"")
B55: =IF($O55="","",INDEX(tblVideos[Day],$O55)) | D55: =IF($O55="","",INDEX(tblVideos[Channel],$O55)) | F55: =IF($O55="","",IF(INDEX(tblVideos[Video ID],$O55)="",INDEX(tblVideos[Title],$O55),HYPERLINK("https://www.youtube.com/watch?v="&INDEX(tblVideos[Video ID],$O55),INDEX(tblVideos[Title],$O55)))) | L55: =IF($O55="","",INDEX(tblVideos[Length],$O55)) | M55: =IF($O55="","",INDEX(tblVideos[Status],$O55)) | O55: =IFERROR(MATCH(MAX(tblVideos[Seq])-7,tblVideos[Seq],0),"")
B56: =IF($O56="","",INDEX(tblVideos[Day],$O56)) | D56: =IF($O56="","",INDEX(tblVideos[Channel],$O56)) | F56: =IF($O56="","",IF(INDEX(tblVideos[Video ID],$O56)="",INDEX(tblVideos[Title],$O56),HYPERLINK("https://www.youtube.com/watch?v="&INDEX(tblVideos[Video ID],$O56),INDEX(tblVideos[Title],$O56)))) | L56: =IF($O56="","",INDEX(tblVideos[Length],$O56)) | M56: =IF($O56="","",INDEX(tblVideos[Status],$O56)) | O56: =IFERROR(MATCH(MAX(tblVideos[Seq])-8,tblVideos[Seq],0),"")
B57: =IF($O57="","",INDEX(tblVideos[Day],$O57)) | D57: =IF($O57="","",INDEX(tblVideos[Channel],$O57)) | F57: =IF($O57="","",IF(INDEX(tblVideos[Video ID],$O57)="",INDEX(tblVideos[Title],$O57),HYPERLINK("https://www.youtube.com/watch?v="&INDEX(tblVideos[Video ID],$O57),INDEX(tblVideos[Title],$O57)))) | L57: =IF($O57="","",INDEX(tblVideos[Length],$O57)) | M57: =IF($O57="","",INDEX(tblVideos[Status],$O57)) | O57: =IFERROR(MATCH(MAX(tblVideos[Seq])-9,tblVideos[Seq],0),"")

Sheet Library
A1: Video Library
A2: Slate columns come from YouTube and are refreshed by the updater. Teal columns are calculated. Gold columns (Mark, Watched On, Notes) are YOURS and are never overwritten.
A3: =HYPERLINK("#Dashboard!A1","◄ Dashboard")
A5: Open | B5: Status | C5: Mark | D5: Watched On | E5: Published | F5: Channel | G5: Title | H5: Length | I5: Views | J5: Likes | K5: Comments | L5: Notes | M5: Video ID | N5: Channel ID | O5: Published UTC | P5: Day | Q5: Seq | R5: Availability | S5: First Seen | T5: Last Seen | U5: Description | V5: Cal Key | W5: Queue Key
A6: =IF(M6="","",HYPERLINK("https://www.youtube.com/watch?v="&M6,"▶")) | B6: =IF(C6<>"",C6,IF(P6<=IFERROR(INDEX(tblChannels[Watched Through],MATCH(N6,tblChannels[Channel ID],0)),0),"Watched","Unwatched")) | E6: 46297.417 | F6: Popcorn Culture | G6: Top 100 TV Shows! | Popcorn Culture | H6: 0.077893519 | I6: 209 | J6: 16 | K6: 7 | N6: UCHfIbq9thHPC8yrKjAdJgDA | O6: 46297.583 | P6: 46297 | Q6: 3266 | R6: No Video ID yet | V6: =IF(AND(P6>=Calendar!$K$2,P6<EDATE(Calendar!$K$2,1),OR(Calendar!$K$4="*",N6=Calendar!$K$4)),P6*100+COUNTIFS($P$6:$P$3271,P6,$Q$6:$Q$3271,"<="&Q6,$N$6:$N$3271,Calendar!$K$4),"") | W6: =IF(AND(B6=Queue!$C$4,OR(Queue!$K$4="*",N6=Queue!$K$4)),Q6,"")
A7: =IF(M7="","",HYPERLINK("https://www.youtube.com/watch?v="&M7,"▶")) | B7: =IF(C7<>"",C7,IF(P7<=IFERROR(INDEX(tblChannels[Watched Through],MATCH(N7,tblChannels[Channel ID],0)),0),"Watched","Unwatched")) | E7: 46295.649 | F7: Super Carlin Brothers | G7: Slughorn’s SECRET Son Revealed | H7: 0.011087963 | I7: 62777 | J7: 1573 | K7: 250 | N7: UCKZo4N0lVPccBkSiuyVh4yg | O7: 46295.815 | P7: 46295 | Q7: 3265 | R7: No Video ID yet | V7: =IF(AND(P7>=Calendar!$K$2,P7<EDATE(Calendar!$K$2,1),OR(Calendar!$K$4="*",N7=Calendar!$K$4)),P7*100+COUNTIFS($P$6:$P$3271,P7,$Q$6:$Q$3271,"<="&Q7,$N$6:$N$3271,Calendar!$K$4),"") | W7: =IF(AND(B7=Queue!$C$4,OR(Queue!$K$4="*",N7=Queue!$K$4)),Q7,"")
A8: =IF(M8="","",HYPERLINK("https://www.youtube.com/watch?v="&M8,"▶")) | B8: =IF(C8<>"",C8,IF(P8<=IFERROR(INDEX(tblChannels[Watched Through],MATCH(N8,tblChannels[Channel ID],0)),0),"Watched","Unwatched")) | E8: 46292.417 | F8: Through The Griffin Door | G8: Chapter 15: The Unbreakable Vow | Half-Blood Prince | H8: 0.076793981 | I8: 41173 | J8: 692 | K8: 303 | N8: UCEscP6ETYXWSSvsNrDHekMQ | O8: 46292.583 | P8: 46292 | Q8: 3264 | R8: No Video ID yet | V8: =IF(AND(P8>=Calendar!$K$2,P8<EDATE(Calendar!$K$2,1),OR(Calendar!$K$4="*",N8=Calendar!$K$4)),P8*100+COUNTIFS($P$6:$P$3271,P8,$Q$6:$Q$3271,"<="&Q8,$N$6:$N$3271,Calendar!$K$4),"") | W8: =IF(AND(B8=Queue!$C$4,OR(Queue!$K$4="*",N8=Queue!$K$4)),Q8,"")
A9: =IF(M9="","",HYPERLINK("https://www.youtube.com/watch?v="&M9,"▶")) | B9: =IF(C9<>"",C9,IF(P9<=IFERROR(INDEX(tblChannels[Watched Through],MATCH(N9,tblChannels[Channel ID],0)),0),"Watched","Unwatched")) | E9: 46290.682 | F9: Super Carlin Brothers | G9: J vs Ben: How Well Do We Know The Boy Who Lived (MAX DIFFICULTY) | H9: 0.034791667 | I9: 102063 | J9: 1791 | K9: 297 | N9: UCKZo4N0lVPccBkSiuyVh4yg | O9: 46290.849 | P9: 46290 | Q9: 3263 | R9: No Video ID yet | V9: =IF(AND(P9>=Calendar!$K$2,P9<EDATE(Calendar!$K$2,1),OR(Calendar!$K$4="*",N9=Calendar!$K$4)),P9*100+COUNTIFS($P$6:$P$3271,P9,$Q$6:$Q$3271,"<="&Q9,$N$6:$N$3271,Calendar!$K$4),"") | W9: =IF(AND(B9=Queue!$C$4,OR(Queue!$K$4="*",N9=Queue!$K$4)),Q9,"")
A10: =IF(M10="","",HYPERLINK("https://www.youtube.com/watch?v="&M10,"▶")) | B10: =IF(C10<>"",C10,IF(P10<=IFERROR(INDEX(tblChannels[Watched Through],MATCH(N10,tblChannels[Channel ID],0)),0),"Watched","Unwatched")) | E10: 46290.417 | F10: Popcorn Culture | G10: Tour in a Podshell | Popcorn Culture | H10: 0.047337963 | I10: 3615 | J10: 90 | K10: 18 | N10: UCHfIbq9thHPC8yrKjAdJgDA | O10: 46290.583 | P10: 46290 | Q10: 3262 | R10: No Video ID yet | V10: =IF(AND(P10>=Calendar!$K$2,P10<EDATE(Calendar!$K$2,1),OR(Calendar!$K$4="*",N10=Calendar!$K$4)),P10*100+COUNTIFS($P$6:$P$3271,P10,$Q$6:$Q$3271,"<="&Q10,$N$6:$N$3271,Calendar!$K$4),"") | W10: =IF(AND(B10=Queue!$C$4,OR(Queue!$K$4="*",N10=Queue!$K$4)),Q10,"")
A11: =IF(M11="","",HYPERLINK("https://www.youtube.com/watch?v="&M11,"▶")) | B11: =IF(C11<>"",C11,IF(P11<=IFERROR(INDEX(tblChannels[Watched Through],MATCH(N11,tblChannels[Channel ID],0)),0),"Watched","Unwatched")) | E11: 46289.653 | F11: Popcorn Culture | G11: Mr. Ben's Worst Day Ever | Popcorn Culture | H11: 0.0026273148 | I11: 2235 | J11: 118 | K11: 27 | N11: UCHfIbq9thHPC8yrKjAdJgDA | O11: 46289.82 | P11: 46289 | Q11: 3261 | R11: No Video ID yet | V11: =IF(AND(P11>=Calendar!$K$2,P11<EDATE(Calendar!$K$2,1),OR(Calendar!$K$4="*",N11=Calendar!$K$4)),P11*100+COUNTIFS($P$6:$P$3271,P11,$Q$6:$Q$3271,"<="&Q11,$N$6:$N$3271,Calendar!$K$4),"") | W11: =IF(AND(B11=Queue!$C$4,OR(Queue!$K$4="*",N11=Queue!$K$4)),Q11,"")
A12: =IF(M12="","",HYPERLINK("https://www.youtube.com/watch?v="&M12,"▶")) | B12: =IF(C12<>"",C12,IF(P12<=IFERROR(INDEX(tblChannels[Watched Through],MATCH(N12,tblChannels[Channel ID],0)),0),"Watched","Unwatched")) | E12: 46288.674 | F12: Super Carlin Brothers | G12: Slughorn’s SECRET Role In Creating Voldemort | H12: 0.011018519 | I12: 188618 | J12: 3039 | K12: 280 | N12: UCKZo4N0lVPccBkSiuyVh4yg | O12: 46288.841 | P12: 46288 | Q12: 3260 | R12: No Video ID yet | V12: =IF(AND(P12>=Calendar!$K$2,P12<EDATE(Calendar!$K$2,1),OR(Calendar!$K$4="*",N12=Calendar!$K$4)),P12*100+COUNTIFS($P$6:$P$3271,P12,$Q$6:$Q$3271,"<="&Q12,$N$6:$N$3271,Calendar!$K$4),"") | W12: =IF(AND(B12=Queue!$C$4,OR(Queue!$K$4="*",N12=Queue!$K$4)),Q12,"")
A13: =IF(M13="","",HYPERLINK("https://www.youtube.com/watch?v="&M13,"▶")) | B13: =IF(C13<>"",C13,IF(P13<=IFERROR(INDEX(tblChannels[Watched Through],MATCH(N13,tblChannels[Channel ID],0)),0),"Watched","Unwatched")) | E13: 46285.417 | F13: Through The Griffin Door | G13: The Owlery Special Part 5! | H13: 0.054189815 | I13: 25554 | J13: 452 | K13: 122 | N13: UCEscP6ETYXWSSvsNrDHekMQ | O13: 46285.583 | P13: 46285 | Q13: 3259 | R13: No Video ID yet | V13: =IF(AND(P13>=Calendar!$K$2,P13<EDATE(Calendar!$K$2,1),OR(Calendar!$K$4="*",N13=Calendar!$K$4)),P13*100+COUNTIFS($P$6:$P$3271,P13,$Q$6:$Q$3271,"<="&Q13,$N$6:$N$3271,Calendar!$K$4),"") | W13: =IF(AND(B13=Queue!$C$4,OR(Queue!$K$4="*",N13=Queue!$K$4)),Q13,"")
A14: =IF(M14="","",HYPERLINK("https://www.youtube.com/watch?v="&M14,"▶")) | B14: =IF(C14<>"",C14,IF(P14<=IFERROR(INDEX(tblChannels[Watched Through],MATCH(N14,tblChannels[Channel ID],0)),0),"Watched","Unwatched")) | E14: 46283.625 | F14: Super Carlin Brothers | G14: J & Ben VS AI - Harry Potter Trivia | H14: 0.031261574 | I14: 115261 | J14: 2389 | K14: 450 | N14: UCKZo4N0lVPccBkSiuyVh4yg | O14: 46283.792 | P14: 46283 | Q14: 3258 | R14: No Video ID yet | V14: =IF(AND(P14>=Calendar!$K$2,P14<EDATE(Calendar!$K$2,1),OR(Calendar!$K$4="*",N14=Calendar!$K$4)),P14*100+COUNTIFS($P$6:$P$3271,P14,$Q$6:$Q$3271,"<="&Q14,$N$6:$N$3271,Calendar!$K$4),"") | W14: =IF(AND(B14=Queue!$C$4,OR(Queue!$K$4="*",N14=Queue!$K$4)),Q14,"")
A15: =IF(M15="","",HYPERLINK("https://www.youtube.com/watch?v="&M15,"▶")) | B15: =IF(C15<>"",C15,IF(P15<=IFERROR(INDEX(tblChannels[Watched Through],MATCH(N15,tblChannels[Channel ID],0)),0),"Watched","Unwatched")) | E15: 46283.417 | F15: Popcorn Culture | G15: The Roanoke Bracket | Popcorn Culture | H15: 0.050405093 | I15: 3167 | J15: 96 | K15: 22 | N15: UCHfIbq9thHPC8yrKjAdJgDA | O15: 46283.583 | P15: 46283 | Q15: 3257 | R15: No Video ID yet | V15: =IF(AND(P15>=Calendar!$K$2,P15<EDATE(Calendar!$K$2,1),OR(Calendar!$K$4="*",N15=Calendar!$K$4)),P15*100+COUNTIFS($P$6:$P$3271,P15,$Q$6:$Q$3271,"<="&Q15,$N$6:$N$3271,Calendar!$K$4),"") | W15: =IF(AND(B15=Queue!$C$4,OR(Queue!$K$4="*",N15=Queue!$K$4)),Q15,"")
A16: =IF(M16="","",HYPERLINK("https://www.youtube.com/watch?v="&M16,"▶")) | B16: =IF(C16<>"",C16,IF(P16<=IFERROR(INDEX(tblChannels[Watched Through],MATCH(N16,tblChannels[Channel ID],0)),0),"Watched","Unwatched")) | E16: 46281.625 | F16: Super Carlin Brothers | G16: Theories From A Hat: Defending MORE Wild Harry Potter Theories | H16: 0.0271875 | I16: 104475 | J16: 1972 | K16: 409 | N16: UCKZo4N0lVPccBkSiuyVh4yg | O16: 46281.792 | P16: 46281 | Q16: 3256 | R16: No Video ID yet | V16: =IF(AND(P16>=Calendar!$K$2,P16<EDATE(Calendar!$K$2,1),OR(Calendar!$K$4="*",N16=Calendar!$K$4)),P16*100+COUNTIFS($P$6:$P$3271,P16,$Q$6:$Q$3271,"<="&Q16,$N$6:$N$3271,Calendar!$K$4),"") | W16: =IF(AND(B16=Queue!$C$4,OR(Queue!$K$4="*",N16=Queue!$K$4)),Q16,"")
A17: =IF(M17="","",HYPERLINK("https://www.youtube.com/watch?v="&M17,"▶")) | B17: =IF(C17<>"",C17,IF(P17<=IFERROR(INDEX(tblChannels[Watched Through],MATCH(N17,tblChannels[Channel ID],0)),0),"Watched","Unwatched")) | E17: 46278.476 | F17: Through The Griffin Door | G17: Chapter 14: Felix Felicis | Half-Blood Prince | H17: 0.079710648 | I17: 38643 | J17: 813 | K17: 243 | N17: UCEscP6ETYXWSSvsNrDHekMQ | O17: 46278.642 | P17: 46278 | Q17: 3255 | R17: No Video ID yet | V17: =IF(AND(P17>=Calendar!$K$2,P17<EDATE(Calendar!$K$2,1),OR(Calendar!$K$4="*",N17=Calendar!$K$4)),P17*100+COUNTIFS($P$6:$P$3271,P17,$Q$6:$Q$3271,"<="&Q17,$N$6:$N$3271,Calendar!$K$4),"") | W17: =IF(AND(B17=Queue!$C$4,OR(Queue!$K$4="*",N17=Queue!$K$4)),Q17,"")
... A3271: =IF(M3271="","",HYPERLINK("https://www.youtube.com/watch?v="&M3271,"▶")) | B3271: =IF(C3271<>"",C3271,IF(P3271<=IFERROR(INDEX(tblChannels[Watched Through],MATCH(N3271,tblChannels[Channel ID],0)),0),"Watched","Unwatched")) | E3271: 41058.985 | F3271: Super Carlin Brothers | G3271: Super Carlin Brothers Teaser | H3271: 0.00025462963 | I3271: 146050 | J3271: 2475 | K3271: 271 | N3271: UCKZo4N0lVPccBkSiuyVh4yg | O3271: 41059.151 | P3271: 41058 | Q3271: 1 | R3271: No Video ID yet | V3271: =IF(AND(P3271>=Calendar!$K$2,P3271<EDATE(Calendar!$K$2,1),OR(Calendar!$K$4="*",N3271=Calendar!$K$4)),P3271*100+COUNTIFS($P$6:$P$3271,P3271,$Q$6:$Q$3271,"<="&Q3271,$N$6:$N$3271,Calendar!$K$4),"") | W3271: =IF(AND(B3271=Queue!$C$4,OR(Queue!$K$4="*",N3271=Queue!$K$4)),Q3271,"")

Sheet Queue
B2: Watch Queue
C3: Show | D3: Channel | E3: Order
B4: =HYPERLINK("#Dashboard!A1","◄ Dashboard") | C4: Unwatched | D4: All channels | E4: Oldest first | K4: =IF($D$4="All channels","*",IFERROR(INDEX(tblChannels[Channel ID],MATCH($D$4,tblChannels[Display Name],0)),"none"))
B5: =COUNT(tblVideos[Queue Key])&" videos match · "&TEXT(SUMIFS(tblVideos[Length],tblVideos[Queue Key],">0"),"[h]:mm")&" of runtime"
B6: Your next videos. Click a title to open it on YouTube; mark it watched in the Library.
B7: # | C7: Published | D7: Channel | E7: Title | F7: Length | G7: Status
B8: =IF($I8="","",1) | C8: =IF($I8="","",INDEX(tblVideos[Day],$I8)) | D8: =IF($I8="","",INDEX(tblVideos[Channel],$I8)) | E8: =IF($I8="","",IF(INDEX(tblVideos[Video ID],$I8)="",INDEX(tblVideos[Title],$I8),HYPERLINK("https://www.youtube.com/watch?v="&INDEX(tblVideos[Video ID],$I8),INDEX(tblVideos[Title],$I8)))) | F8: =IF($I8="","",INDEX(tblVideos[Length],$I8)) | G8: =IF($I8="","",INDEX(tblVideos[Status],$I8)) | I8: =IFERROR(MATCH(IF($E$4="Newest first",LARGE(tblVideos[Queue Key],1),SMALL(tblVideos[Queue Key],1)),tblVideos[Seq],0),"")
B9: =IF($I9="","",2) | C9: =IF($I9="","",INDEX(tblVideos[Day],$I9)) | D9: =IF($I9="","",INDEX(tblVideos[Channel],$I9)) | E9: =IF($I9="","",IF(INDEX(tblVideos[Video ID],$I9)="",INDEX(tblVideos[Title],$I9),HYPERLINK("https://www.youtube.com/watch?v="&INDEX(tblVideos[Video ID],$I9),INDEX(tblVideos[Title],$I9)))) | F9: =IF($I9="","",INDEX(tblVideos[Length],$I9)) | G9: =IF($I9="","",INDEX(tblVideos[Status],$I9)) | I9: =IFERROR(MATCH(IF($E$4="Newest first",LARGE(tblVideos[Queue Key],2),SMALL(tblVideos[Queue Key],2)),tblVideos[Seq],0),"")
B10: =IF($I10="","",3) | C10: =IF($I10="","",INDEX(tblVideos[Day],$I10)) | D10: =IF($I10="","",INDEX(tblVideos[Channel],$I10)) | E10: =IF($I10="","",IF(INDEX(tblVideos[Video ID],$I10)="",INDEX(tblVideos[Title],$I10),HYPERLINK("https://www.youtube.com/watch?v="&INDEX(tblVideos[Video ID],$I10),INDEX(tblVideos[Title],$I10)))) | F10: =IF($I10="","",INDEX(tblVideos[Length],$I10)) | G10: =IF($I10="","",INDEX(tblVideos[Status],$I10)) | I10: =IFERROR(MATCH(IF($E$4="Newest first",LARGE(tblVideos[Queue Key],3),SMALL(tblVideos[Queue Key],3)),tblVideos[Seq],0),"")
B11: =IF($I11="","",4) | C11: =IF($I11="","",INDEX(tblVideos[Day],$I11)) | D11: =IF($I11="","",INDEX(tblVideos[Channel],$I11)) | E11: =IF($I11="","",IF(INDEX(tblVideos[Video ID],$I11)="",INDEX(tblVideos[Title],$I11),HYPERLINK("https://www.youtube.com/watch?v="&INDEX(tblVideos[Video ID],$I11),INDEX(tblVideos[Title],$I11)))) | F11: =IF($I11="","",INDEX(tblVideos[Length],$I11)) | G11: =IF($I11="","",INDEX(tblVideos[Status],$I11)) | I11: =IFERROR(MATCH(IF($E$4="Newest first",LARGE(tblVideos[Queue Key],4),SMALL(tblVideos[Queue Key],4)),tblVideos[Seq],0),"")
B12: =IF($I12="","",5) | C12: =IF($I12="","",INDEX(tblVideos[Day],$I12)) | D12: =IF($I12="","",INDEX(tblVideos[Channel],$I12)) | E12: =IF($I12="","",IF(INDEX(tblVideos[Video ID],$I12)="",INDEX(tblVideos[Title],$I12),HYPERLINK("https://www.youtube.com/watch?v="&INDEX(tblVideos[Video ID],$I12),INDEX(tblVideos[Title],$I12)))) | F12: =IF($I12="","",INDEX(tblVideos[Length],$I12)) | G12: =IF($I12="","",INDEX(tblVideos[Status],$I12)) | I12: =IFERROR(MATCH(IF($E$4="Newest first",LARGE(tblVideos[Queue Key],5),SMALL(tblVideos[Queue Key],5)),tblVideos[Seq],0),"")
B13: =IF($I13="","",6) | C13: =IF($I13="","",INDEX(tblVideos[Day],$I13)) | D13: =IF($I13="","",INDEX(tblVideos[Channel],$I13)) | E13: =IF($I13="","",IF(INDEX(tblVideos[Video ID],$I13)="",INDEX(tblVideos[Title],$I13),HYPERLINK("https://www.youtube.com/watch?v="&INDEX(tblVideos[Video ID],$I13),INDEX(tblVideos[Title],$I13)))) | F13: =IF($I13="","",INDEX(tblVideos[Length],$I13)) | G13: =IF($I13="","",INDEX(tblVideos[Status],$I13)) | I13: =IFERROR(MATCH(IF($E$4="Newest first",LARGE(tblVideos[Queue Key],6),SMALL(tblVideos[Queue Key],6)),tblVideos[Seq],0),"")
B14: =IF($I14="","",7) | C14: =IF($I14="","",INDEX(tblVideos[Day],$I14)) | D14: =IF($I14="","",INDEX(tblVideos[Channel],$I14)) | E14: =IF($I14="","",IF(INDEX(tblVideos[Video ID],$I14)="",INDEX(tblVideos[Title],$I14),HYPERLINK("https://www.youtube.com/watch?v="&INDEX(tblVideos[Video ID],$I14),INDEX(tblVideos[Title],$I14)))) | F14: =IF($I14="","",INDEX(tblVideos[Length],$I14)) | G14: =IF($I14="","",INDEX(tblVideos[Status],$I14)) | I14: =IFERROR(MATCH(IF($E$4="Newest first",LARGE(tblVideos[Queue Key],7),SMALL(tblVideos[Queue Key],7)),tblVideos[Seq],0),"")
B15: =IF($I15="","",8) | C15: =IF($I15="","",INDEX(tblVideos[Day],$I15)) | D15: =IF($I15="","",INDEX(tblVideos[Channel],$I15)) | E15: =IF($I15="","",IF(INDEX(tblVideos[Video ID],$I15)="",INDEX(tblVideos[Title],$I15),HYPERLINK("https://www.youtube.com/watch?v="&INDEX(tblVideos[Video ID],$I15),INDEX(tblVideos[Title],$I15)))) | F15: =IF($I15="","",INDEX(tblVideos[Length],$I15)) | G15: =IF($I15="","",INDEX(tblVideos[Status],$I15)) | I15: =IFERROR(MATCH(IF($E$4="Newest first",LARGE(tblVideos[Queue Key],8),SMALL(tblVideos[Queue Key],8)),tblVideos[Seq],0),"")
B16: =IF($I16="","",9) | C16: =IF($I16="","",INDEX(tblVideos[Day],$I16)) | D16: =IF($I16="","",INDEX(tblVideos[Channel],$I16)) | E16: =IF($I16="","",IF(INDEX(tblVideos[Video ID],$I16)="",INDEX(tblVideos[Title],$I16),HYPERLINK("https://www.youtube.com/watch?v="&INDEX(tblVideos[Video ID],$I16),INDEX(tblVideos[Title],$I16)))) | F16: =IF($I16="","",INDEX(tblVideos[Length],$I16)) | G16: =IF($I16="","",INDEX(tblVideos[Status],$I16)) | I16: =IFERROR(MATCH(IF($E$4="Newest first",LARGE(tblVideos[Queue Key],9),SMALL(tblVideos[Queue Key],9)),tblVideos[Seq],0),"")
B17: =IF($I17="","",10) | C17: =IF($I17="","",INDEX(tblVideos[Day],$I17)) | D17: =IF($I17="","",INDEX(tblVideos[Channel],$I17)) | E17: =IF($I17="","",IF(INDEX(tblVideos[Video ID],$I17)="",INDEX(tblVideos[Title],$I17),HYPERLINK("https://www.youtube.com/watch?v="&INDEX(tblVideos[Video ID],$I17),INDEX(tblVideos[Title],$I17)))) | F17: =IF($I17="","",INDEX(tblVideos[Length],$I17)) | G17: =IF($I17="","",INDEX(tblVideos[Status],$I17)) | I17: =IFERROR(MATCH(IF($E$4="Newest first",LARGE(tblVideos[Queue Key],10),SMALL(tblVideos[Queue Key],10)),tblVideos[Seq],0),"")
B18: =IF($I18="","",11) | C18: =IF($I18="","",INDEX(tblVideos[Day],$I18)) | D18: =IF($I18="","",INDEX(tblVideos[Channel],$I18)) | E18: =IF($I18="","",IF(INDEX(tblVideos[Video ID],$I18)="",INDEX(tblVideos[Title],$I18),HYPERLINK("https://www.youtube.com/watch?v="&INDEX(tblVideos[Video ID],$I18),INDEX(tblVideos[Title],$I18)))) | F18: =IF($I18="","",INDEX(tblVideos[Length],$I18)) | G18: =IF($I18="","",INDEX(tblVideos[Status],$I18)) | I18: =IFERROR(MATCH(IF($E$4="Newest first",LARGE(tblVideos[Queue Key],11),SMALL(tblVideos[Queue Key],11)),tblVideos[Seq],0),"")
B19: =IF($I19="","",12) | C19: =IF($I19="","",INDEX(tblVideos[Day],$I19)) | D19: =IF($I19="","",INDEX(tblVideos[Channel],$I19)) | E19: =IF($I19="","",IF(INDEX(tblVideos[Video ID],$I19)="",INDEX(tblVideos[Title],$I19),HYPERLINK("https://www.youtube.com/watch?v="&INDEX(tblVideos[Video ID],$I19),INDEX(tblVideos[Title],$I19)))) | F19: =IF($I19="","",INDEX(tblVideos[Length],$I19)) | G19: =IF($I19="","",INDEX(tblVideos[Status],$I19)) | I19: =IFERROR(MATCH(IF($E$4="Newest first",LARGE(tblVideos[Queue Key],12),SMALL(tblVideos[Queue Key],12)),tblVideos[Seq],0),"")
B20: =IF($I20="","",13) | C20: =IF($I20="","",INDEX(tblVideos[Day],$I20)) | D20: =IF($I20="","",INDEX(tblVideos[Channel],$I20)) | E20: =IF($I20="","",IF(INDEX(tblVideos[Video ID],$I20)="",INDEX(tblVideos[Title],$I20),HYPERLINK("https://www.youtube.com/watch?v="&INDEX(tblVideos[Video ID],$I20),INDEX(tblVideos[Title],$I20)))) | F20: =IF($I20="","",INDEX(tblVideos[Length],$I20)) | G20: =IF($I20="","",INDEX(tblVideos[Status],$I20)) | I20: =IFERROR(MATCH(IF($E$4="Newest first",LARGE(tblVideos[Queue Key],13),SMALL(tblVideos[Queue Key],13)),tblVideos[Seq],0),"")
B21: =IF($I21="","",14) | C21: =IF($I21="","",INDEX(tblVideos[Day],$I21)) | D21: =IF($I21="","",INDEX(tblVideos[Channel],$I21)) | E21: =IF($I21="","",IF(INDEX(tblVideos[Video ID],$I21)="",INDEX(tblVideos[Title],$I21),HYPERLINK("https://www.youtube.com/watch?v="&INDEX(tblVideos[Video ID],$I21),INDEX(tblVideos[Title],$I21)))) | F21: =IF($I21="","",INDEX(tblVideos[Length],$I21)) | G21: =IF($I21="","",INDEX(tblVideos[Status],$I21)) | I21: =IFERROR(MATCH(IF($E$4="Newest first",LARGE(tblVideos[Queue Key],14),SMALL(tblVideos[Queue Key],14)),tblVideos[Seq],0),"")
B22: =IF($I22="","",15) | C22: =IF($I22="","",INDEX(tblVideos[Day],$I22)) | D22: =IF($I22="","",INDEX(tblVideos[Channel],$I22)) | E22: =IF($I22="","",IF(INDEX(tblVideos[Video ID],$I22)="",INDEX(tblVideos[Title],$I22),HYPERLINK("https://www.youtube.com/watch?v="&INDEX(tblVideos[Video ID],$I22),INDEX(tblVideos[Title],$I22)))) | F22: =IF($I22="","",INDEX(tblVideos[Length],$I22)) | G22: =IF($I22="","",INDEX(tblVideos[Status],$I22)) | I22: =IFERROR(MATCH(IF($E$4="Newest first",LARGE(tblVideos[Queue Key],15),SMALL(tblVideos[Queue Key],15)),tblVideos[Seq],0),"")
B23: =IF($I23="","",16) | C23: =IF($I23="","",INDEX(tblVideos[Day],$I23)) | D23: =IF($I23="","",INDEX(tblVideos[Channel],$I23)) | E23: =IF($I23="","",IF(INDEX(tblVideos[Video ID],$I23)="",INDEX(tblVideos[Title],$I23),HYPERLINK("https://www.youtube.com/watch?v="&INDEX(tblVideos[Video ID],$I23),INDEX(tblVideos[Title],$I23)))) | F23: =IF($I23="","",INDEX(tblVideos[Length],$I23)) | G23: =IF($I23="","",INDEX(tblVideos[Status],$I23)) | I23: =IFERROR(MATCH(IF($E$4="Newest first",LARGE(tblVideos[Queue Key],16),SMALL(tblVideos[Queue Key],16)),tblVideos[Seq],0),"")
B24: =IF($I24="","",17) | C24: =IF($I24="","",INDEX(tblVideos[Day],$I24)) | D24: =IF($I24="","",INDEX(tblVideos[Channel],$I24)) | E24: =IF($I24="","",IF(INDEX(tblVideos[Video ID],$I24)="",INDEX(tblVideos[Title],$I24),HYPERLINK("https://www.youtube.com/watch?v="&INDEX(tblVideos[Video ID],$I24),INDEX(tblVideos[Title],$I24)))) | F24: =IF($I24="","",INDEX(tblVideos[Length],$I24)) | G24: =IF($I24="","",INDEX(tblVideos[Status],$I24)) | I24: =IFERROR(MATCH(IF($E$4="Newest first",LARGE(tblVideos[Queue Key],17),SMALL(tblVideos[Queue Key],17)),tblVideos[Seq],0),"")
B25: =IF($I25="","",18) | C25: =IF($I25="","",INDEX(tblVideos[Day],$I25)) | D25: =IF($I25="","",INDEX(tblVideos[Channel],$I25)) | E25: =IF($I25="","",IF(INDEX(tblVideos[Video ID],$I25)="",INDEX(tblVideos[Title],$I25),HYPERLINK("https://www.youtube.com/watch?v="&INDEX(tblVideos[Video ID],$I25),INDEX(tblVideos[Title],$I25)))) | F25: =IF($I25="","",INDEX(tblVideos[Length],$I25)) | G25: =IF($I25="","",INDEX(tblVideos[Status],$I25)) | I25: =IFERROR(MATCH(IF($E$4="Newest first",LARGE(tblVideos[Queue Key],18),SMALL(tblVideos[Queue Key],18)),tblVideos[Seq],0),"")
B26: =IF($I26="","",19) | C26: =IF($I26="","",INDEX(tblVideos[Day],$I26)) | D26: =IF($I26="","",INDEX(tblVideos[Channel],$I26)) | E26: =IF($I26="","",IF(INDEX(tblVideos[Video ID],$I26)="",INDEX(tblVideos[Title],$I26),HYPERLINK("https://www.youtube.com/watch?v="&INDEX(tblVideos[Video ID],$I26),INDEX(tblVideos[Title],$I26)))) | F26: =IF($I26="","",INDEX(tblVideos[Length],$I26)) | G26: =IF($I26="","",INDEX(tblVideos[Status],$I26)) | I26: =IFERROR(MATCH(IF($E$4="Newest first",LARGE(tblVideos[Queue Key],19),SMALL(tblVideos[Queue Key],19)),tblVideos[Seq],0),"")
B27: =IF($I27="","",20) | C27: =IF($I27="","",INDEX(tblVideos[Day],$I27)) | D27: =IF($I27="","",INDEX(tblVideos[Channel],$I27)) | E27: =IF($I27="","",IF(INDEX(tblVideos[Video ID],$I27)="",INDEX(tblVideos[Title],$I27),HYPERLINK("https://www.youtube.com/watch?v="&INDEX(tblVideos[Video ID],$I27),INDEX(tblVideos[Title],$I27)))) | F27: =IF($I27="","",INDEX(tblVideos[Length],$I27)) | G27: =IF($I27="","",INDEX(tblVideos[Status],$I27)) | I27: =IFERROR(MATCH(IF($E$4="Newest first",LARGE(tblVideos[Queue Key],20),SMALL(tblVideos[Queue Key],20)),tblVideos[Seq],0),"")
B28: =IF($I28="","",21) | C28: =IF($I28="","",INDEX(tblVideos[Day],$I28)) | D28: =IF($I28="","",INDEX(tblVideos[Channel],$I28)) | E28: =IF($I28="","",IF(INDEX(tblVideos[Video ID],$I28)="",INDEX(tblVideos[Title],$I28),HYPERLINK("https://www.youtube.com/watch?v="&INDEX(tblVideos[Video ID],$I28),INDEX(tblVideos[Title],$I28)))) | F28: =IF($I28="","",INDEX(tblVideos[Length],$I28)) | G28: =IF($I28="","",INDEX(tblVideos[Status],$I28)) | I28: =IFERROR(MATCH(IF($E$4="Newest first",LARGE(tblVideos[Queue Key],21),SMALL(tblVideos[Queue Key],21)),tblVideos[Seq],0),"")
B29: =IF($I29="","",22) | C29: =IF($I29="","",INDEX(tblVideos[Day],$I29)) | D29: =IF($I29="","",INDEX(tblVideos[Channel],$I29)) | E29: =IF($I29="","",IF(INDEX(tblVideos[Video ID],$I29)="",INDEX(tblVideos[Title],$I29),HYPERLINK("https://www.youtube.com/watch?v="&INDEX(tblVideos[Video ID],$I29),INDEX(tblVideos[Title],$I29)))) | F29: =IF($I29="","",INDEX(tblVideos[Length],$I29)) | G29: =IF($I29="","",INDEX(tblVideos[Status],$I29)) | I29: =IFERROR(MATCH(IF($E$4="Newest first",LARGE(tblVideos[Queue Key],22),SMALL(tblVideos[Queue Key],22)),tblVideos[Seq],0),"")
B30: =IF($I30="","",23) | C30: =IF($I30="","",INDEX(tblVideos[Day],$I30)) | D30: =IF($I30="","",INDEX(tblVideos[Channel],$I30)) | E30: =IF($I30="","",IF(INDEX(tblVideos[Video ID],$I30)="",INDEX(tblVideos[Title],$I30),HYPERLINK("https://www.youtube.com/watch?v="&INDEX(tblVideos[Video ID],$I30),INDEX(tblVideos[Title],$I30)))) | F30: =IF($I30="","",INDEX(tblVideos[Length],$I30)) | G30: =IF($I30="","",INDEX(tblVideos[Status],$I30)) | I30: =IFERROR(MATCH(IF($E$4="Newest first",LARGE(tblVideos[Queue Key],23),SMALL(tblVideos[Queue Key],23)),tblVideos[Seq],0),"")
B31: =IF($I31="","",24) | C31: =IF($I31="","",INDEX(tblVideos[Day],$I31)) | D31: =IF($I31="","",INDEX(tblVideos[Channel],$I31)) | E31: =IF($I31="","",IF(INDEX(tblVideos[Video ID],$I31)="",INDEX(tblVideos[Title],$I31),HYPERLINK("https://www.youtube.com/watch?v="&INDEX(tblVideos[Video ID],$I31),INDEX(tblVideos[Title],$I31)))) | F31: =IF($I31="","",INDEX(tblVideos[Length],$I31)) | G31: =IF($I31="","",INDEX(tblVideos[Status],$I31)) | I31: =IFERROR(MATCH(IF($E$4="Newest first",LARGE(tblVideos[Queue Key],24),SMALL(tblVideos[Queue Key],24)),tblVideos[Seq],0),"")
B32: =IF($I32="","",25) | C32: =IF($I32="","",INDEX(tblVideos[Day],$I32)) | D32: =IF($I32="","",INDEX(tblVideos[Channel],$I32)) | E32: =IF($I32="","",IF(INDEX(tblVideos[Video ID],$I32)="",INDEX(tblVideos[Title],$I32),HYPERLINK("https://www.youtube.com/watch?v="&INDEX(tblVideos[Video ID],$I32),INDEX(tblVideos[Title],$I32)))) | F32: =IF($I32="","",INDEX(tblVideos[Length],$I32)) | G32: =IF($I32="","",INDEX(tblVideos[Status],$I32)) | I32: =IFERROR(MATCH(IF($E$4="Newest first",LARGE(tblVideos[Queue Key],25),SMALL(tblVideos[Queue Key],25)),tblVideos[Seq],0),"")
B33: =IF($I33="","",26) | C33: =IF($I33="","",INDEX(tblVideos[Day],$I33)) | D33: =IF($I33="","",INDEX(tblVideos[Channel],$I33)) | E33: =IF($I33="","",IF(INDEX(tblVideos[Video ID],$I33)="",INDEX(tblVideos[Title],$I33),HYPERLINK("https://www.youtube.com/watch?v="&INDEX(tblVideos[Video ID],$I33),INDEX(tblVideos[Title],$I33)))) | F33: =IF($I33="","",INDEX(tblVideos[Length],$I33)) | G33: =IF($I33="","",INDEX(tblVideos[Status],$I33)) | I33: =IFERROR(MATCH(IF($E$4="Newest first",LARGE(tblVideos[Queue Key],26),SMALL(tblVideos[Queue Key],26)),tblVideos[Seq],0),"")
B34: =IF($I34="","",27) | C34: =IF($I34="","",INDEX(tblVideos[Day],$I34)) | D34: =IF($I34="","",INDEX(tblVideos[Channel],$I34)) | E34: =IF($I34="","",IF(INDEX(tblVideos[Video ID],$I34)="",INDEX(tblVideos[Title],$I34),HYPERLINK("https://www.youtube.com/watch?v="&INDEX(tblVideos[Video ID],$I34),INDEX(tblVideos[Title],$I34)))) | F34: =IF($I34="","",INDEX(tblVideos[Length],$I34)) | G34: =IF($I34="","",INDEX(tblVideos[Status],$I34)) | I34: =IFERROR(MATCH(IF($E$4="Newest first",LARGE(tblVideos[Queue Key],27),SMALL(tblVideos[Queue Key],27)),tblVideos[Seq],0),"")
B35: =IF($I35="","",28) | C35: =IF($I35="","",INDEX(tblVideos[Day],$I35)) | D35: =IF($I35="","",INDEX(tblVideos[Channel],$I35)) | E35: =IF($I35="","",IF(INDEX(tblVideos[Video ID],$I35)="",INDEX(tblVideos[Title],$I35),HYPERLINK("https://www.youtube.com/watch?v="&INDEX(tblVideos[Video ID],$I35),INDEX(tblVideos[Title],$I35)))) | F35: =IF($I35="","",INDEX(tblVideos[Length],$I35)) | G35: =IF($I35="","",INDEX(tblVideos[Status],$I35)) | I35: =IFERROR(MATCH(IF($E$4="Newest first",LARGE(tblVideos[Queue Key],28),SMALL(tblVideos[Queue Key],28)),tblVideos[Seq],0),"")
B36: =IF($I36="","",29) | C36: =IF($I36="","",INDEX(tblVideos[Day],$I36)) | D36: =IF($I36="","",INDEX(tblVideos[Channel],$I36)) | E36: =IF($I36="","",IF(INDEX(tblVideos[Video ID],$I36)="",INDEX(tblVideos[Title],$I36),HYPERLINK("https://www.youtube.com/watch?v="&INDEX(tblVideos[Video ID],$I36),INDEX(tblVideos[Title],$I36)))) | F36: =IF($I36="","",INDEX(tblVideos[Length],$I36)) | G36: =IF($I36="","",INDEX(tblVideos[Status],$I36)) | I36: =IFERROR(MATCH(IF($E$4="Newest first",LARGE(tblVideos[Queue Key],29),SMALL(tblVideos[Queue Key],29)),tblVideos[Seq],0),"")
B37: =IF($I37="","",30) | C37: =IF($I37="","",INDEX(tblVideos[Day],$I37)) | D37: =IF($I37="","",INDEX(tblVideos[Channel],$I37)) | E37: =IF($I37="","",IF(INDEX(tblVideos[Video ID],$I37)="",INDEX(tblVideos[Title],$I37),HYPERLINK("https://www.youtube.com/watch?v="&INDEX(tblVideos[Video ID],$I37),INDEX(tblVideos[Title],$I37)))) | F37: =IF($I37="","",INDEX(tblVideos[Length],$I37)) | G37: =IF($I37="","",INDEX(tblVideos[Status],$I37)) | I37: =IFERROR(MATCH(IF($E$4="Newest first",LARGE(tblVideos[Queue Key],30),SMALL(tblVideos[Queue Key],30)),tblVideos[Seq],0),"")

Sheet Calendar
B2: Upload Calendar | J2: month start | K2: =DATE($C$4,MATCH($E$4,MonthList,0),1)
C3: Year | E3: Month | G3: Channel | J3: grid start | K3: =K2-(WEEKDAY(K2,2)-1)
B4: =HYPERLINK("#Dashboard!A1","◄ Dashboard") | C4: 2026 | E4: October | G4: All channels | J4: channel crit | K4: =IF($G$4="All channels","*",IFERROR(INDEX(tblChannels[Channel ID],MATCH($G$4,tblChannels[Display Name],0)),"none"))
B5: Pick a year, month and (optionally) a channel with the dropdowns. Click a title to open it on YouTube. ✓ = watched, dimmed.
B6: ="Videos: "&COUNTIFS(tblVideos[Day],">="&$K$2,tblVideos[Day],"<"&EDATE($K$2,1),tblVideos[Channel ID],$K$4)&" Runtime: "&TEXT(SUMIFS(tblVideos[Length],tblVideos[Day],">="&$K$2,tblVideos[Day],"<"&EDATE($K$2,1),tblVideos[Channel ID],$K$4),"[h]:mm")&" Watched: "&COUNTIFS(tblVideos[Day],">="&$K$2,tblVideos[Day],"<"&EDATE($K$2,1),tblVideos[Channel ID],$K$4,tblVideos[Status],"Watched")&" of "&COUNTIFS(tblVideos[Day],">="&$K$2,tblVideos[Day],"<"&EDATE($K$2,1),tblVideos[Channel ID],$K$4)
B7: =Channels!$C$6&" ("&COUNTIFS(tblVideos[Day],">="&$K$2,tblVideos[Day],"<"&EDATE($K$2,1),tblVideos[Channel ID],Channels!$E$6)&")" | C7: =Channels!$C$7&" ("&COUNTIFS(tblVideos[Day],">="&$K$2,tblVideos[Day],"<"&EDATE($K$2,1),tblVideos[Channel ID],Channels!$E$7)&")" | D7: =Channels!$C$8&" ("&COUNTIFS(tblVideos[Day],">="&$K$2,tblVideos[Day],"<"&EDATE($K$2,1),tblVideos[Channel ID],Channels!$E$8)&")" | E7: =Channels!$C$9&" ("&COUNTIFS(tblVideos[Day],">="&$K$2,tblVideos[Day],"<"&EDATE($K$2,1),tblVideos[Channel ID],Channels!$E$9)&")" | F7: =Channels!$C$10&" ("&COUNTIFS(tblVideos[Day],">="&$K$2,tblVideos[Day],"<"&EDATE($K$2,1),tblVideos[Channel ID],Channels!$E$10)&")" | G7: =Channels!$C$11&" ("&COUNTIFS(tblVideos[Day],">="&$K$2,tblVideos[Day],"<"&EDATE($K$2,1),tblVideos[Channel ID],Channels!$E$11)&")"
B9: Monday | C9: Tuesday | D9: Wednesday | E9: Thursday | F9: Friday | G9: Saturday | H9: Sunday
B10: =IF(MONTH(K10)=MONTH($K$2),DAY(K10)&IF(S10>0," · "&S10&IF(S10=1," video"," videos")&" · "&TEXT(AA10,"[h]:mm")&IF(S10>5," (+"&(S10-5)&" more)",""),""),"") | C10: =IF(MONTH(L10)=MONTH($K$2),DAY(L10)&IF(T10>0," · "&T10&IF(T10=1," video"," videos")&" · "&TEXT(AB10,"[h]:mm")&IF(T10>5," (+"&(T10-5)&" more)",""),""),"") | D10: =IF(MONTH(M10)=MONTH($K$2),DAY(M10)&IF(U10>0," · "&U10&IF(U10=1," video"," videos")&" · "&TEXT(AC10,"[h]:mm")&IF(U10>5," (+"&(U10-5)&" more)",""),""),"") | E10: =IF(MONTH(N10)=MONTH($K$2),DAY(N10)&IF(V10>0," · "&V10&IF(V10=1," video"," videos")&" · "&TEXT(AD10,"[h]:mm")&IF(V10>5," (+"&(V10-5)&" more)",""),""),"") | F10: =IF(MONTH(O10)=MONTH($K$2),DAY(O10)&IF(W10>0," · "&W10&IF(W10=1," video"," videos")&" · "&TEXT(AE10,"[h]:mm")&IF(W10>5," (+"&(W10-5)&" more)",""),""),"") | G10: =IF(MONTH(P10)=MONTH($K$2),DAY(P10)&IF(X10>0," · "&X10&IF(X10=1," video"," videos")&" · "&TEXT(AF10,"[h]:mm")&IF(X10>5," (+"&(X10-5)&" more)",""),""),"") | H10: =IF(MONTH(Q10)=MONTH($K$2),DAY(Q10)&IF(Y10>0," · "&Y10&IF(Y10=1," video"," videos")&" · "&TEXT(AG10,"[h]:mm")&IF(Y10>5," (+"&(Y10-5)&" more)",""),""),"") | K10: =$K$3+0 | L10: =$K$3+1 | M10: =$K$3+2 | N10: =$K$3+3 | O10: =$K$3+4 | P10: =$K$3+5 | Q10: =$K$3+6 | S10: =IF(MONTH(K10)=MONTH($K$2),COUNTIFS(tblVideos[Day],K10,tblVideos[Channel ID],$K$4),0) | T10: =IF(MONTH(L10)=MONTH($K$2),COUNTIFS(tblVideos[Day],L10,tblVideos[Channel ID],$K$4),0) | U10: =IF(MONTH(M10)=MONTH($K$2),COUNTIFS(tblVideos[Day],M10,tblVideos[Channel ID],$K$4),0) | V10: =IF(MONTH(N10)=MONTH($K$2),COUNTIFS(tblVideos[Day],N10,tblVideos[Channel ID],$K$4),0) | W10: =IF(MONTH(O10)=MONTH($K$2),COUNTIFS(tblVideos[Day],O10,tblVideos[Channel ID],$K$4),0) | X10: =IF(MONTH(P10)=MONTH($K$2),COUNTIFS(tblVideos[Day],P10,tblVideos[Channel ID],$K$4),0) | Y10: =IF(MONTH(Q10)=MONTH($K$2),COUNTIFS(tblVideos[Day],Q10,tblVideos[Channel ID],$K$4),0) | AA10: =IF(S10>0,SUMIFS(tblVideos[Length],tblVideos[Day],K10,tblVideos[Channel ID],$K$4),0) | AB10: =IF(T10>0,SUMIFS(tblVideos[Length],tblVideos[Day],L10,tblVideos[Channel ID],$K$4),0) | AC10: =IF(U10>0,SUMIFS(tblVideos[Length],tblVideos[Day],M10,tblVideos[Channel ID],$K$4),0) | AD10: =IF(V10>0,SUMIFS(tblVideos[Length],tblVideos[Day],N10,tblVideos[Channel ID],$K$4),0) | AE10: =IF(W10>0,SUMIFS(tblVideos[Length],tblVideos[Day],O10,tblVideos[Channel ID],$K$4),0) | AF10: =IF(X10>0,SUMIFS(tblVideos[Length],tblVideos[Day],P10,tblVideos[Channel ID],$K$4),0) | AG10: =IF(Y10>0,SUMIFS(tblVideos[Length],tblVideos[Day],Q10,tblVideos[Channel ID],$K$4),0)
B11: =IF(K11="","",IF(INDEX(tblVideos[Video ID],K11)="",IF(INDEX(tblVideos[Status],K11)="Watched","✓ ","▸ ")&INDEX(tblVideos[Title],K11),HYPERLINK("https://www.youtube.com/watch?v="&INDEX(tblVideos[Video ID],K11),IF(INDEX(tblVideos[Status],K11)="Watched","✓ ","▸ ")&INDEX(tblVideos[Title],K11)))) | C11: =IF(L11="","",IF(INDEX(tblVideos[Video ID],L11)="",IF(INDEX(tblVideos[Status],L11)="Watched","✓ ","▸ ")&INDEX(tblVideos[Title],L11),HYPERLINK("https://www.youtube.com/watch?v="&INDEX(tblVideos[Video ID],L11),IF(INDEX(tblVideos[Status],L11)="Watched","✓ ","▸ ")&INDEX(tblVideos[Title],L11)))) | D11: =IF(M11="","",IF(INDEX(tblVideos[Video ID],M11)="",IF(INDEX(tblVideos[Status],M11)="Watched","✓ ","▸ ")&INDEX(tblVideos[Title],M11),HYPERLINK("https://www.youtube.com/watch?v="&INDEX(tblVideos[Video ID],M11),IF(INDEX(tblVideos[Status],M11)="Watched","✓ ","▸ ")&INDEX(tblVideos[Title],M11)))) | E11: =IF(N11="","",IF(INDEX(tblVideos[Video ID],N11)="",IF(INDEX(tblVideos[Status],N11)="Watched","✓ ","▸ ")&INDEX(tblVideos[Title],N11),HYPERLINK("https://www.youtube.com/watch?v="&INDEX(tblVideos[Video ID],N11),IF(INDEX(tblVideos[Status],N11)="Watched","✓ ","▸ ")&INDEX(tblVideos[Title],N11)))) | F11: =IF(O11="","",IF(INDEX(tblVideos[Video ID],O11)="",IF(INDEX(tblVideos[Status],O11)="Watched","✓ ","▸ ")&INDEX(tblVideos[Title],O11),HYPERLINK("https://www.youtube.com/watch?v="&INDEX(tblVideos[Video ID],O11),IF(INDEX(tblVideos[Status],O11)="Watched","✓ ","▸ ")&INDEX(tblVideos[Title],O11)))) | G11: =IF(P11="","",IF(INDEX(tblVideos[Video ID],P11)="",IF(INDEX(tblVideos[Status],P11)="Watched","✓ ","▸ ")&INDEX(tblVideos[Title],P11),HYPERLINK("https://www.youtube.com/watch?v="&INDEX(tblVideos[Video ID],P11),IF(INDEX(tblVideos[Status],P11)="Watched","✓ ","▸ ")&INDEX(tblVideos[Title],P11)))) | H11: =IF(Q11="","",IF(INDEX(tblVideos[Video ID],Q11)="",IF(INDEX(tblVideos[Status],Q11)="Watched","✓ ","▸ ")&INDEX(tblVideos[Title],Q11),HYPERLINK("https://www.youtube.com/watch?v="&INDEX(tblVideos[Video ID],Q11),IF(INDEX(tblVideos[Status],Q11)="Watched","✓ ","▸ ")&INDEX(tblVideos[Title],Q11)))) | K11: =IF(S10>=1,MATCH(K10*100+1,tblVideos[Cal Key],0),"") | L11: =IF(T10>=1,MATCH(L10*100+1,tblVideos[Cal Key],0),"") | M11: =IF(U10>=1,MATCH(M10*100+1,tblVideos[Cal Key],0),"") | N11: =IF(V10>=1,MATCH(N10*100+1,tblVideos[Cal Key],0),"") | O11: =IF(W10>=1,MATCH(O10*100+1,tblVideos[Cal Key],0),"") | P11: =IF(X10>=1,MATCH(P10*100+1,tblVideos[Cal Key],0),"") | Q11: =IF(Y10>=1,MATCH(Q10*100+1,tblVideos[Cal Key],0),"") | S11: =IF(K11="","",IFERROR(MATCH(INDEX(tblVideos[Channel ID],K11),tblChannels[Channel ID],0),"")) | T11: =IF(L11="","",IFERROR(MATCH(INDEX(tblVideos[Channel ID],L11),tblChannels[Channel ID],0),"")) | U11: =IF(M11="","",IFERROR(MATCH(INDEX(tblVideos[Channel ID],M11),tblChannels[Channel ID],0),"")) | V11: =IF(N11="","",IFERROR(MATCH(INDEX(tblVideos[Channel ID],N11),tblChannels[Channel ID],0),"")) | W11: =IF(O11="","",IFERROR(MATCH(INDEX(tblVideos[Channel ID],O11),tblChannels[Channel ID],0),"")) | X11: =IF(P11="","",IFERROR(MATCH(INDEX(tblVideos[Channel ID],P11),tblChannels[Channel ID],0),"")) | Y11: =IF(Q11="","",IFERROR(MATCH(INDEX(tblVideos[Channel ID],Q11),tblChannels[Channel ID],0),""))
B12: =IF(K12="","",IF(INDEX(tblVideos[Video ID],K12)="",IF(INDEX(tblVideos[Status],K12)="Watched","✓ ","▸ ")&INDEX(tblVideos[Title],K12),HYPERLINK("https://www.youtube.com/watch?v="&INDEX(tblVideos[Video ID],K12),IF(INDEX(tblVideos[Status],K12)="Watched","✓ ","▸ ")&INDEX(tblVideos[Title],K12)))) | C12: =IF(L12="","",IF(INDEX(tblVideos[Video ID],L12)="",IF(INDEX(tblVideos[Status],L12)="Watched","✓ ","▸ ")&INDEX(tblVideos[Title],L12),HYPERLINK("https://www.youtube.com/watch?v="&INDEX(tblVideos[Video ID],L12),IF(INDEX(tblVideos[Status],L12)="Watched","✓ ","▸ ")&INDEX(tblVideos[Title],L12)))) | D12: =IF(M12="","",IF(INDEX(tblVideos[Video ID],M12)="",IF(INDEX(tblVideos[Status],M12)="Watched","✓ ","▸ ")&INDEX(tblVideos[Title],M12),HYPERLINK("https://www.youtube.com/watch?v="&INDEX(tblVideos[Video ID],M12),IF(INDEX(tblVideos[Status],M12)="Watched","✓ ","▸ ")&INDEX(tblVideos[Title],M12)))) | E12: =IF(N12="","",IF(INDEX(tblVideos[Video ID],N12)="",IF(INDEX(tblVideos[Status],N12)="Watched","✓ ","▸ ")&INDEX(tblVideos[Title],N12),HYPERLINK("https://www.youtube.com/watch?v="&INDEX(tblVideos[Video ID],N12),IF(INDEX(tblVideos[Status],N12)="Watched","✓ ","▸ ")&INDEX(tblVideos[Title],N12)))) | F12: =IF(O12="","",IF(INDEX(tblVideos[Video ID],O12)="",IF(INDEX(tblVideos[Status],O12)="Watched","✓ ","▸ ")&INDEX(tblVideos[Title],O12),HYPERLINK("https://www.youtube.com/watch?v="&INDEX(tblVideos[Video ID],O12),IF(INDEX(tblVideos[Status],O12)="Watched","✓ ","▸ ")&INDEX(tblVideos[Title],O12)))) | G12: =IF(P12="","",IF(INDEX(tblVideos[Video ID],P12)="",IF(INDEX(tblVideos[Status],P12)="Watched","✓ ","▸ ")&INDEX(tblVideos[Title],P12),HYPERLINK("https://www.youtube.com/watch?v="&INDEX(tblVideos[Video ID],P12),IF(INDEX(tblVideos[Status],P12)="Watched","✓ ","▸ ")&INDEX(tblVideos[Title],P12)))) | H12: =IF(Q12="","",IF(INDEX(tblVideos[Video ID],Q12)="",IF(INDEX(tblVideos[Status],Q12)="Watched","✓ ","▸ ")&INDEX(tblVideos[Title],Q12),HYPERLINK("https://www.youtube.com/watch?v="&INDEX(tblVideos[Video ID],Q12),IF(INDEX(tblVideos[Status],Q12)="Watched","✓ ","▸ ")&INDEX(tblVideos[Title],Q12)))) | K12: =IF(S10>=2,MATCH(K10*100+2,tblVideos[Cal Key],0),"") | L12: =IF(T10>=2,MATCH(L10*100+2,tblVideos[Cal Key],0),"") | M12: =IF(U10>=2,MATCH(M10*100+2,tblVideos[Cal Key],0),"") | N12: =IF(V10>=2,MATCH(N10*100+2,tblVideos[Cal Key],0),"") | O12: =IF(W10>=2,MATCH(O10*100+2,tblVideos[Cal Key],0),"") | P12: =IF(X10>=2,MATCH(P10*100+2,tblVideos[Cal Key],0),"") | Q12: =IF(Y10>=2,MATCH(Q10*100+2,tblVideos[Cal Key],0),"") | S12: =IF(K12="","",IFERROR(MATCH(INDEX(tblVideos[Channel ID],K12),tblChannels[Channel ID],0),"")) | T12: =IF(L12="","",IFERROR(MATCH(INDEX(tblVideos[Channel ID],L12),tblChannels[Channel ID],0),"")) | U12: =IF(M12="","",IFERROR(MATCH(INDEX(tblVideos[Channel ID],M12),tblChannels[Channel ID],0),"")) | V12: =IF(N12="","",IFERROR(MATCH(INDEX(tblVideos[Channel ID],N12),tblChannels[Channel ID],0),"")) | W12: =IF(O12="","",IFERROR(MATCH(INDEX(tblVideos[Channel ID],O12),tblChannels[Channel ID],0),"")) | X12: =IF(P12="","",IFERROR(MATCH(INDEX(tblVideos[Channel ID],P12),tblChannels[Channel ID],0),"")) | Y12: =IF(Q12="","",IFERROR(MATCH(INDEX(tblVideos[Channel ID],Q12),tblChannels[Channel ID],0),""))
B13: =IF(K13="","",IF(INDEX(tblVideos[Video ID],K13)="",IF(INDEX(tblVideos[Status],K13)="Watched","✓ ","▸ ")&INDEX(tblVideos[Title],K13),HYPERLINK("https://www.youtube.com/watch?v="&INDEX(tblVideos[Video ID],K13),IF(INDEX(tblVideos[Status],K13)="Watched","✓ ","▸ ")&INDEX(tblVideos[Title],K13)))) | C13: =IF(L13="","",IF(INDEX(tblVideos[Video ID],L13)="",IF(INDEX(tblVideos[Status],L13)="Watched","✓ ","▸ ")&INDEX(tblVideos[Title],L13),HYPERLINK("https://www.youtube.com/watch?v="&INDEX(tblVideos[Video ID],L13),IF(INDEX(tblVideos[Status],L13)="Watched","✓ ","▸ ")&INDEX(tblVideos[Title],L13)))) | D13: =IF(M13="","",IF(INDEX(tblVideos[Video ID],M13)="",IF(INDEX(tblVideos[Status],M13)="Watched","✓ ","▸ ")&INDEX(tblVideos[Title],M13),HYPERLINK("https://www.youtube.com/watch?v="&INDEX(tblVideos[Video ID],M13),IF(INDEX(tblVideos[Status],M13)="Watched","✓ ","▸ ")&INDEX(tblVideos[Title],M13)))) | E13: =IF(N13="","",IF(INDEX(tblVideos[Video ID],N13)="",IF(INDEX(tblVideos[Status],N13)="Watched","✓ ","▸ ")&INDEX(tblVideos[Title],N13),HYPERLINK("https://www.youtube.com/watch?v="&INDEX(tblVideos[Video ID],N13),IF(INDEX(tblVideos[Status],N13)="Watched","✓ ","▸ ")&INDEX(tblVideos[Title],N13)))) | F13: =IF(O13="","",IF(INDEX(tblVideos[Video ID],O13)="",IF(INDEX(tblVideos[Status],O13)="Watched","✓ ","▸ ")&INDEX(tblVideos[Title],O13),HYPERLINK("https://www.youtube.com/watch?v="&INDEX(tblVideos[Video ID],O13),IF(INDEX(tblVideos[Status],O13)="Watched","✓ ","▸ ")&INDEX(tblVideos[Title],O13)))) | G13: =IF(P13="","",IF(INDEX(tblVideos[Video ID],P13)="",IF(INDEX(tblVideos[Status],P13)="Watched","✓ ","▸ ")&INDEX(tblVideos[Title],P13),HYPERLINK("https://www.youtube.com/watch?v="&INDEX(tblVideos[Video ID],P13),IF(INDEX(tblVideos[Status],P13)="Watched","✓ ","▸ ")&INDEX(tblVideos[Title],P13)))) | H13: =IF(Q13="","",IF(INDEX(tblVideos[Video ID],Q13)="",IF(INDEX(tblVideos[Status],Q13)="Watched","✓ ","▸ ")&INDEX(tblVideos[Title],Q13),HYPERLINK("https://www.youtube.com/watch?v="&INDEX(tblVideos[Video ID],Q13),IF(INDEX(tblVideos[Status],Q13)="Watched","✓ ","▸ ")&INDEX(tblVideos[Title],Q13)))) | K13: =IF(S10>=3,MATCH(K10*100+3,tblVideos[Cal Key],0),"") | L13: =IF(T10>=3,MATCH(L10*100+3,tblVideos[Cal Key],0),"") | M13: =IF(U10>=3,MATCH(M10*100+3,tblVideos[Cal Key],0),"") | N13: =IF(V10>=3,MATCH(N10*100+3,tblVideos[Cal Key],0),"") | O13: =IF(W10>=3,MATCH(O10*100+3,tblVideos[Cal Key],0),"") | P13: =IF(X10>=3,MATCH(P10*100+3,tblVideos[Cal Key],0),"") | Q13: =IF(Y10>=3,MATCH(Q10*100+3,tblVideos[Cal Key],0),"") | S13: =IF(K13="","",IFERROR(MATCH(INDEX(tblVideos[Channel ID],K13),tblChannels[Channel ID],0),"")) | T13: =IF(L13="","",IFERROR(MATCH(INDEX(tblVideos[Channel ID],L13),tblChannels[Channel ID],0),"")) | U13: =IF(M13="","",IFERROR(MATCH(INDEX(tblVideos[Channel ID],M13),tblChannels[Channel ID],0),"")) | V13: =IF(N13="","",IFERROR(MATCH(INDEX(tblVideos[Channel ID],N13),tblChannels[Channel ID],0),"")) | W13: =IF(O13="","",IFERROR(MATCH(INDEX(tblVideos[Channel ID],O13),tblChannels[Channel ID],0),"")) | X13: =IF(P13="","",IFERROR(MATCH(INDEX(tblVideos[Channel ID],P13),tblChannels[Channel ID],0),"")) | Y13: =IF(Q13="","",IFERROR(MATCH(INDEX(tblVideos[Channel ID],Q13),tblChannels[Channel ID],0),""))
B14: =IF(K14="","",IF(INDEX(tblVideos[Video ID],K14)="",IF(INDEX(tblVideos[Status],K14)="Watched","✓ ","▸ ")&INDEX(tblVideos[Title],K14),HYPERLINK("https://www.youtube.com/watch?v="&INDEX(tblVideos[Video ID],K14),IF(INDEX(tblVideos[Status],K14)="Watched","✓ ","▸ ")&INDEX(tblVideos[Title],K14)))) | C14: =IF(L14="","",IF(INDEX(tblVideos[Video ID],L14)="",IF(INDEX(tblVideos[Status],L14)="Watched","✓ ","▸ ")&INDEX(tblVideos[Title],L14),HYPERLINK("https://www.youtube.com/watch?v="&INDEX(tblVideos[Video ID],L14),IF(INDEX(tblVideos[Status],L14)="Watched","✓ ","▸ ")&INDEX(tblVideos[Title],L14)))) | D14: =IF(M14="","",IF(INDEX(tblVideos[Video ID],M14)="",IF(INDEX(tblVideos[Status],M14)="Watched","✓ ","▸ ")&INDEX(tblVideos[Title],M14),HYPERLINK("https://www.youtube.com/watch?v="&INDEX(tblVideos[Video ID],M14),IF(INDEX(tblVideos[Status],M14)="Watched","✓ ","▸ ")&INDEX(tblVideos[Title],M14)))) | E14: =IF(N14="","",IF(INDEX(tblVideos[Video ID],N14)="",IF(INDEX(tblVideos[Status],N14)="Watched","✓ ","▸ ")&INDEX(tblVideos[Title],N14),HYPERLINK("https://www.youtube.com/watch?v="&INDEX(tblVideos[Video ID],N14),IF(INDEX(tblVideos[Status],N14)="Watched","✓ ","▸ ")&INDEX(tblVideos[Title],N14)))) | F14: =IF(O14="","",IF(INDEX(tblVideos[Video ID],O14)="",IF(INDEX(tblVideos[Status],O14)="Watched","✓ ","▸ ")&INDEX(tblVideos[Title],O14),HYPERLINK("https://www.youtube.com/watch?v="&INDEX(tblVideos[Video ID],O14),IF(INDEX(tblVideos[Status],O14)="Watched","✓ ","▸ ")&INDEX(tblVideos[Title],O14)))) | G14: =IF(P14="","",IF(INDEX(tblVideos[Video ID],P14)="",IF(INDEX(tblVideos[Status],P14)="Watched","✓ ","▸ ")&INDEX(tblVideos[Title],P14),HYPERLINK("https://www.youtube.com/watch?v="&INDEX(tblVideos[Video ID],P14),IF(INDEX(tblVideos[Status],P14)="Watched","✓ ","▸ ")&INDEX(tblVideos[Title],P14)))) | H14: =IF(Q14="","",IF(INDEX(tblVideos[Video ID],Q14)="",IF(INDEX(tblVideos[Status],Q14)="Watched","✓ ","▸ ")&INDEX(tblVideos[Title],Q14),HYPERLINK("https://www.youtube.com/watch?v="&INDEX(tblVideos[Video ID],Q14),IF(INDEX(tblVideos[Status],Q14)="Watched","✓ ","▸ ")&INDEX(tblVideos[Title],Q14)))) | K14: =IF(S10>=4,MATCH(K10*100+4,tblVideos[Cal Key],0),"") | L14: =IF(T10>=4,MATCH(L10*100+4,tblVideos[Cal Key],0),"") | M14: =IF(U10>=4,MATCH(M10*100+4,tblVideos[Cal Key],0),"") | N14: =IF(V10>=4,MATCH(N10*100+4,tblVideos[Cal Key],0),"") | O14: =IF(W10>=4,MATCH(O10*100+4,tblVideos[Cal Key],0),"") | P14: =IF(X10>=4,MATCH(P10*100+4,tblVideos[Cal Key],0),"") | Q14: =IF(Y10>=4,MATCH(Q10*100+4,tblVideos[Cal Key],0),"") | S14: =IF(K14="","",IFERROR(MATCH(INDEX(tblVideos[Channel ID],K14),tblChannels[Channel ID],0),"")) | T14: =IF(L14="","",IFERROR(MATCH(INDEX(tblVideos[Channel ID],L14),tblChannels[Channel ID],0),"")) | U14: =IF(M14="","",IFERROR(MATCH(INDEX(tblVideos[Channel ID],M14),tblChannels[Channel ID],0),"")) | V14: =IF(N14="","",IFERROR(MATCH(INDEX(tblVideos[Channel ID],N14),tblChannels[Channel ID],0),"")) | W14: =IF(O14="","",IFERROR(MATCH(INDEX(tblVideos[Channel ID],O14),tblChannels[Channel ID],0),"")) | X14: =IF(P14="","",IFERROR(MATCH(INDEX(tblVideos[Channel ID],P14),tblChannels[Channel ID],0),"")) | Y14: =IF(Q14="","",IFERROR(MATCH(INDEX(tblVideos[Channel ID],Q14),tblChannels[Channel ID],0),""))
B15: =IF(K15="","",IF(INDEX(tblVideos[Video ID],K15)="",IF(INDEX(tblVideos[Status],K15)="Watched","✓ ","▸ ")&INDEX(tblVideos[Title],K15),HYPERLINK("https://www.youtube.com/watch?v="&INDEX(tblVideos[Video ID],K15),IF(INDEX(tblVideos[Status],K15)="Watched","✓ ","▸ ")&INDEX(tblVideos[Title],K15)))) | C15: =IF(L15="","",IF(INDEX(tblVideos[Video ID],L15)="",IF(INDEX(tblVideos[Status],L15)="Watched","✓ ","▸ ")&INDEX(tblVideos[Title],L15),HYPERLINK("https://www.youtube.com/watch?v="&INDEX(tblVideos[Video ID],L15),IF(INDEX(tblVideos[Status],L15)="Watched","✓ ","▸ ")&INDEX(tblVideos[Title],L15)))) | D15: =IF(M15="","",IF(INDEX(tblVideos[Video ID],M15)="",IF(INDEX(tblVideos[Status],M15)="Watched","✓ ","▸ ")&INDEX(tblVideos[Title],M15),HYPERLINK("https://www.youtube.com/watch?v="&INDEX(tblVideos[Video ID],M15),IF(INDEX(tblVideos[Status],M15)="Watched","✓ ","▸ ")&INDEX(tblVideos[Title],M15)))) | E15: =IF(N15="","",IF(INDEX(tblVideos[Video ID],N15)="",IF(INDEX(tblVideos[Status],N15)="Watched","✓ ","▸ ")&INDEX(tblVideos[Title],N15),HYPERLINK("https://www.youtube.com/watch?v="&INDEX(tblVideos[Video ID],N15),IF(INDEX(tblVideos[Status],N15)="Watched","✓ ","▸ ")&INDEX(tblVideos[Title],N15)))) | F15: =IF(O15="","",IF(INDEX(tblVideos[Video ID],O15)="",IF(INDEX(tblVideos[Status],O15)="Watched","✓ ","▸ ")&INDEX(tblVideos[Title],O15),HYPERLINK("https://www.youtube.com/watch?v="&INDEX(tblVideos[Video ID],O15),IF(INDEX(tblVideos[Status],O15)="Watched","✓ ","▸ ")&INDEX(tblVideos[Title],O15)))) | G15: =IF(P15="","",IF(INDEX(tblVideos[Video ID],P15)="",IF(INDEX(tblVideos[Status],P15)="Watched","✓ ","▸ ")&INDEX(tblVideos[Title],P15),HYPERLINK("https://www.youtube.com/watch?v="&INDEX(tblVideos[Video ID],P15),IF(INDEX(tblVideos[Status],P15)="Watched","✓ ","▸ ")&INDEX(tblVideos[Title],P15)))) | H15: =IF(Q15="","",IF(INDEX(tblVideos[Video ID],Q15)="",IF(INDEX(tblVideos[Status],Q15)="Watched","✓ ","▸ ")&INDEX(tblVideos[Title],Q15),HYPERLINK("https://www.youtube.com/watch?v="&INDEX(tblVideos[Video ID],Q15),IF(INDEX(tblVideos[Status],Q15)="Watched","✓ ","▸ ")&INDEX(tblVideos[Title],Q15)))) | K15: =IF(S10>=5,MATCH(K10*100+5,tblVideos[Cal Key],0),"") | L15: =IF(T10>=5,MATCH(L10*100+5,tblVideos[Cal Key],0),"") | M15: =IF(U10>=5,MATCH(M10*100+5,tblVideos[Cal Key],0),"") | N15: =IF(V10>=5,MATCH(N10*100+5,tblVideos[Cal Key],0),"") | O15: =IF(W10>=5,MATCH(O10*100+5,tblVideos[Cal Key],0),"") | P15: =IF(X10>=5,MATCH(P10*100+5,tblVideos[Cal Key],0),"") | Q15: =IF(Y10>=5,MATCH(Q10*100+5,tblVideos[Cal Key],0),"") | S15: =IF(K15="","",IFERROR(MATCH(INDEX(tblVideos[Channel ID],K15),tblChannels[Channel ID],0),"")) | T15: =IF(L15="","",IFERROR(MATCH(INDEX(tblVideos[Channel ID],L15),tblChannels[Channel ID],0),"")) | U15: =IF(M15="","",IFERROR(MATCH(INDEX(tblVideos[Channel ID],M15),tblChannels[Channel ID],0),"")) | V15: =IF(N15="","",IFERROR(MATCH(INDEX(tblVideos[Channel ID],N15),tblChannels[Channel ID],0),"")) | W15: =IF(O15="","",IFERROR(MATCH(INDEX(tblVideos[Channel ID],O15),tblChannels[Channel ID],0),"")) | X15: =IF(P15="","",IFERROR(MATCH(INDEX(tblVideos[Channel ID],P15),tblChannels[Channel ID],0),"")) | Y15: =IF(Q15="","",IFERROR(MATCH(INDEX(tblVideos[Channel ID],Q15),tblChannels[Channel ID],0),""))
