Workbook
Name YearList: Lists!$A$1:$A$15
Name MonthList: Lists!$C$1:$C$12
Name ChannelList: OFFSET(Lists!$E$1,0,0,COUNTIF(Lists!$E$1:$E$40,"?*"),1)

Sheet Dashboard
B2: SCB Video Library
B3: =IF(Settings!$C$5="","","Last updated "&TEXT(Settings!$C$5,"d mmm yyyy h:mm AM/PM")&" · "&TODAY()-INT(Settings!$C$5)&" day(s) ago")
B4: =HYPERLINK("#Library!A1","Library") | C4: =HYPERLINK("#Queue!A1","Queue") | D4: =HYPERLINK("#Calendar!A1","Calendar") | E4: =HYPERLINK("#History!A1","History") | F4: =HYPERLINK("#Stats!A1","Stats") | G4: =HYPERLINK("#Channels!A1","Channels") | H4: =HYPERLINK("#Settings!A1","Settings")
B6: TOTAL VIDEOS | D6: WATCHED | F6: BACKLOG | H6: % WATCHED | J6: HOURS WATCHED | L6: HOURS REMAINING
B7: =Stats!C14 | D7: =Stats!D14 | F7: =Stats!E14+Stats!F14 | H7: =Stats!H14 | J7: =Stats!J14*24 | L7: =Stats!K14*24
B8: ="across "&6&" channels" | D8: ="of "&TEXT(Stats!C14-Stats!G14,"#,##0")&" tracked" | F8: =TEXT(Stats!E14,"#,##0")&" watch-later" | H8: =TEXT(Stats!L14,"0.0%")&" of runtime" | J8: ="of "&TEXT(Stats!I14*24,"#,##0")&" h total" | L8: ="≈ "&TEXT(Stats!K14,"#,##0")&" days of video"
B10: By channel
B11: Channel | E11: Videos | F11: Watched | G11: Backlog | H11: % Watched | I11: Time left | J11: Latest upload | L11: Days since
B12: =Stats!B8 | E12: =Stats!C8 | F12: =Stats!D8 | G12: =Stats!E8+Stats!F8 | H12: =Stats!H8 | I12: =Stats!K8 | J12: =Stats!D20 | L12: =IF(J12="","",TODAY()-J12)
B13: =Stats!B9 | E13: =Stats!C9 | F13: =Stats!D9 | G13: =Stats!E9+Stats!F9 | H13: =Stats!H9 | I13: =Stats!K9 | J13: =Stats!D21 | L13: =IF(J13="","",TODAY()-J13)
B14: =Stats!B10 | E14: =Stats!C10 | F14: =Stats!D10 | G14: =Stats!E10+Stats!F10 | H14: =Stats!H10 | I14: =Stats!K10 | J14: =Stats!D22 | L14: =IF(J14="","",TODAY()-J14)
B15: =Stats!B11 | E15: =Stats!C11 | F15: =Stats!D11 | G15: =Stats!E11+Stats!F11 | H15: =Stats!H11 | I15: =Stats!K11 | J15: =Stats!D23 | L15: =IF(J15="","",TODAY()-J15)
B16: =Stats!B12 | E16: =Stats!C12 | F16: =Stats!D12 | G16: =Stats!E12+Stats!F12 | H16: =Stats!H12 | I16: =Stats!K12 | J16: =Stats!D24 | L16: =IF(J16="","",TODAY()-J16)
B17: =Stats!B13 | E17: =Stats!C13 | F17: =Stats!D13 | G17: =Stats!E13+Stats!F13 | H17: =Stats!H13 | I17: =Stats!K13 | J17: =Stats!D25 | L17: =IF(J17="","",TODAY()-J17)
B18: All channels | E18: =Stats!C14 | F18: =Stats!D14 | G18: =Stats!E14+Stats!F14 | H18: =Stats!H14 | I18: =Stats!K14
B39: Up next - oldest unwatched video in each channel
B40: Channel | E40: Video | L40: Length | M40: Published
B41: =Channels!$C$6 | E41: =IF($O41="","All caught up ✓",IF(INDEX(tblVideos[Video ID],$O41)="",INDEX(tblVideos[Title],$O41),HYPERLINK("https://www.youtube.com/watch?v="&INDEX(tblVideos[Video ID],$O41),INDEX(tblVideos[Title],$O41)))) | L41: =IF($O41="","",INDEX(tblVideos[Length],$O41)) | M41: =IF($O41="","",INDEX(tblVideos[Day],$O41)) | O41: =IF(_xlfn.MINIFS(tblVideos[Seq],tblVideos[Channel ID],Channels!$E$6,tblVideos[Status],"Unwatched")=0,"",MATCH(_xlfn.MINIFS(tblVideos[Seq],tblVideos[Channel ID],Channels!$E$6,tblVideos[Status],"Unwatched"),tblVideos[Seq],0))
B42: =Channels!$C$7 | E42: =IF($O42="","All caught up ✓",IF(INDEX(tblVideos[Video ID],$O42)="",INDEX(tblVideos[Title],$O42),HYPERLINK("https://www.youtube.com/watch?v="&INDEX(tblVideos[Video ID],$O42),INDEX(tblVideos[Title],$O42)))) | L42: =IF($O42="","",INDEX(tblVideos[Length],$O42)) | M42: =IF($O42="","",INDEX(tblVideos[Day],$O42)) | O42: =IF(_xlfn.MINIFS(tblVideos[Seq],tblVideos[Channel ID],Channels!$E$7,tblVideos[Status],"Unwatched")=0,"",MATCH(_xlfn.MINIFS(tblVideos[Seq],tblVideos[Channel ID],Channels!$E$7,tblVideos[Status],"Unwatched"),tblVideos[Seq],0))
B43: =Channels!$C$8 | E43: =IF($O43="","All caught up ✓",IF(INDEX(tblVideos[Video ID],$O43)="",INDEX(tblVideos[Title],$O43),HYPERLINK("https://www.youtube.com/watch?v="&INDEX(tblVideos[Video ID],$O43),INDEX(tblVideos[Title],$O43)))) | L43: =IF($O43="","",INDEX(tblVideos[Length],$O43)) | M43: =IF($O43="","",INDEX(tblVideos[Day],$O43)) | O43: =IF(_xlfn.MINIFS(tblVideos[Seq],tblVideos[Channel ID],Channels!$E$8,tblVideos[Status],"Unwatched")=0,"",MATCH(_xlfn.MINIFS(tblVideos[Seq],tblVideos[Channel ID],Channels!$E$8,tblVideos[Status],"Unwatched"),tblVideos[Seq],0))
B44: =Channels!$C$9 | E44: =IF($O44="","All caught up ✓",IF(INDEX(tblVideos[Video ID],$O44)="",INDEX(tblVideos[Title],$O44),HYPERLINK("https://www.youtube.com/watch?v="&INDEX(tblVideos[Video ID],$O44),INDEX(tblVideos[Title],$O44)))) | L44: =IF($O44="","",INDEX(tblVideos[Length],$O44)) | M44: =IF($O44="","",INDEX(tblVideos[Day],$O44)) | O44: =IF(_xlfn.MINIFS(tblVideos[Seq],tblVideos[Channel ID],Channels!$E$9,tblVideos[Status],"Unwatched")=0,"",MATCH(_xlfn.MINIFS(tblVideos[Seq],tblVideos[Channel ID],Channels!$E$9,tblVideos[Status],"Unwatched"),tblVideos[Seq],0))
B45: =Channels!$C$10 | E45: =IF($O45="","All caught up ✓",IF(INDEX(tblVideos[Video ID],$O45)="",INDEX(tblVideos[Title],$O45),HYPERLINK("https://www.youtube.com/watch?v="&INDEX(tblVideos[Video ID],$O45),INDEX(tblVideos[Title],$O45)))) | L45: =IF($O45="","",INDEX(tblVideos[Length],$O45)) | M45: =IF($O45="","",INDEX(tblVideos[Day],$O45)) | O45: =IF(_xlfn.MINIFS(tblVideos[Seq],tblVideos[Channel ID],Channels!$E$10,tblVideos[Status],"Unwatched")=0,"",MATCH(_xlfn.MINIFS(tblVideos[Seq],tblVideos[Channel ID],Channels!$E$10,tblVideos[Status],"Unwatched"),tblVideos[Seq],0))
B46: =Channels!$C$11 | E46: =IF($O46="","All caught up ✓",IF(INDEX(tblVideos[Video ID],$O46)="",INDEX(tblVideos[Title],$O46),HYPERLINK("https://www.youtube.com/watch?v="&INDEX(tblVideos[Video ID],$O46),INDEX(tblVideos[Title],$O46)))) | L46: =IF($O46="","",INDEX(tblVideos[Length],$O46)) | M46: =IF($O46="","",INDEX(tblVideos[Day],$O46)) | O46: =IF(_xlfn.MINIFS(tblVideos[Seq],tblVideos[Channel ID],Channels!$E$11,tblVideos[Status],"Unwatched")=0,"",MATCH(_xlfn.MINIFS(tblVideos[Seq],tblVideos[Channel ID],Channels!$E$11,tblVideos[Status],"Unwatched"),tblVideos[Seq],0))
B49: Newest uploads
B50: Published | D50: Channel | F50: Title | L50: Length | M50: Status
B51: =IF($O51="","",INDEX(tblVideos[Day],$O51)) | D51: =IF($O51="","",INDEX(tblVideos[Channel],$O51)) | F51: =IF($O51="","",IF(INDEX(tblVideos[Video ID],$O51)="",INDEX(tblVideos[Title],$O51),HYPERLINK("https://www.youtube.com/watch?v="&INDEX(tblVideos[Video ID],$O51),INDEX(tblVideos[Title],$O51)))) | L51: =IF($O51="","",INDEX(tblVideos[Length],$O51)) | M51: =IF($O51="","",INDEX(tblVideos[Status],$O51)) | O51: =IFERROR(MATCH(MAX(tblVideos[Seq])-0,tblVideos[Seq],0),"")
B52: =IF($O52="","",INDEX(tblVideos[Day],$O52)) | D52: =IF($O52="","",INDEX(tblVideos[Channel],$O52)) | F52: =IF($O52="","",IF(INDEX(tblVideos[Video ID],$O52)="",INDEX(tblVideos[Title],$O52),HYPERLINK("https://www.youtube.com/watch?v="&INDEX(tblVideos[Video ID],$O52),INDEX(tblVideos[Title],$O52)))) | L52: =IF($O52="","",INDEX(tblVideos[Length],$O52)) | M52: =IF($O52="","",INDEX(tblVideos[Status],$O52)) | O52: =IFERROR(MATCH(MAX(tblVideos[Seq])-1,tblVideos[Seq],0),"")
B53: =IF($O53="","",INDEX(tblVideos[Day],$O53)) | D53: =IF($O53="","",INDEX(tblVideos[Channel],$O53)) | F53: =IF($O53="","",IF(INDEX(tblVideos[Video ID],$O53)="",INDEX(tblVideos[Title],$O53),HYPERLINK("https://www.youtube.com/watch?v="&INDEX(tblVideos[Video ID],$O53),INDEX(tblVideos[Title],$O53)))) | L53: =IF($O53="","",INDEX(tblVideos[Length],$O53)) | M53: =IF($O53="","",INDEX(tblVideos[Status],$O53)) | O53: =IFERROR(MATCH(MAX(tblVideos[Seq])-2,tblVideos[Seq],0),"")
B54: =IF($O54="","",INDEX(tblVideos[Day],$O54)) | D54: =IF($O54="","",INDEX(tblVideos[Channel],$O54)) | F54: =IF($O54="","",IF(INDEX(tblVideos[Video ID],$O54)="",INDEX(tblVideos[Title],$O54),HYPERLINK("https://www.youtube.com/watch?v="&INDEX(tblVideos[Video ID],$O54),INDEX(tblVideos[Title],$O54)))) | L54: =IF($O54="","",INDEX(tblVideos[Length],$O54)) | M54: =IF($O54="","",INDEX(tblVideos[Status],$O54)) | O54: =IFERROR(MATCH(MAX(tblVideos[Seq])-3,tblVideos[Seq],0),"")
B55: =IF($O55="","",INDEX(tblVideos[Day],$O55)) | D55: =IF($O55="","",INDEX(tblVideos[Channel],$O55)) | F55: =IF($O55="","",IF(INDEX(tblVideos[Video ID],$O55)="",INDEX(tblVideos[Title],$O55),HYPERLINK("https://www.youtube.com/watch?v="&INDEX(tblVideos[Video ID],$O55),INDEX(tblVideos[Title],$O55)))) | L55: =IF($O55="","",INDEX(tblVideos[Length],$O55)) | M55: =IF($O55="","",INDEX(tblVideos[Status],$O55)) | O55: =IFERROR(MATCH(MAX(tblVideos[Seq])-4,tblVideos[Seq],0),"")
B56: =IF($O56="","",INDEX(tblVideos[Day],$O56)) | D56: =IF($O56="","",INDEX(tblVideos[Channel],$O56)) | F56: =IF($O56="","",IF(INDEX(tblVideos[Video ID],$O56)="",INDEX(tblVideos[Title],$O56),HYPERLINK("https://www.youtube.com/watch?v="&INDEX(tblVideos[Video ID],$O56),INDEX(tblVideos[Title],$O56)))) | L56: =IF($O56="","",INDEX(tblVideos[Length],$O56)) | M56: =IF($O56="","",INDEX(tblVideos[Status],$O56)) | O56: =IFERROR(MATCH(MAX(tblVideos[Seq])-5,tblVideos[Seq],0),"")
B57: =IF($O57="","",INDEX(tblVideos[Day],$O57)) | D57: =IF($O57="","",INDEX(tblVideos[Channel],$O57)) | F57: =IF($O57="","",IF(INDEX(tblVideos[Video ID],$O57)="",INDEX(tblVideos[Title],$O57),HYPERLINK("https://www.youtube.com/watch?v="&INDEX(tblVideos[Video ID],$O57),INDEX(tblVideos[Title],$O57)))) | L57: =IF($O57="","",INDEX(tblVideos[Length],$O57)) | M57: =IF($O57="","",INDEX(tblVideos[Status],$O57)) | O57: =IFERROR(MATCH(MAX(tblVideos[Seq])-6,tblVideos[Seq],0),"")
B58: =IF($O58="","",INDEX(tblVideos[Day],$O58)) | D58: =IF($O58="","",INDEX(tblVideos[Channel],$O58)) | F58: =IF($O58="","",IF(INDEX(tblVideos[Video ID],$O58)="",INDEX(tblVideos[Title],$O58),HYPERLINK("https://www.youtube.com/watch?v="&INDEX(tblVideos[Video ID],$O58),INDEX(tblVideos[Title],$O58)))) | L58: =IF($O58="","",INDEX(tblVideos[Length],$O58)) | M58: =IF($O58="","",INDEX(tblVideos[Status],$O58)) | O58: =IFERROR(MATCH(MAX(tblVideos[Seq])-7,tblVideos[Seq],0),"")
B59: =IF($O59="","",INDEX(tblVideos[Day],$O59)) | D59: =IF($O59="","",INDEX(tblVideos[Channel],$O59)) | F59: =IF($O59="","",IF(INDEX(tblVideos[Video ID],$O59)="",INDEX(tblVideos[Title],$O59),HYPERLINK("https://www.youtube.com/watch?v="&INDEX(tblVideos[Video ID],$O59),INDEX(tblVideos[Title],$O59)))) | L59: =IF($O59="","",INDEX(tblVideos[Length],$O59)) | M59: =IF($O59="","",INDEX(tblVideos[Status],$O59)) | O59: =IFERROR(MATCH(MAX(tblVideos[Seq])-8,tblVideos[Seq],0),"")
B60: =IF($O60="","",INDEX(tblVideos[Day],$O60)) | D60: =IF($O60="","",INDEX(tblVideos[Channel],$O60)) | F60: =IF($O60="","",IF(INDEX(tblVideos[Video ID],$O60)="",INDEX(tblVideos[Title],$O60),HYPERLINK("https://www.youtube.com/watch?v="&INDEX(tblVideos[Video ID],$O60),INDEX(tblVideos[Title],$O60)))) | L60: =IF($O60="","",INDEX(tblVideos[Length],$O60)) | M60: =IF($O60="","",INDEX(tblVideos[Status],$O60)) | O60: =IFERROR(MATCH(MAX(tblVideos[Seq])-9,tblVideos[Seq],0),"")

Sheet Library
A1: Video Library
A2: Slate columns come from YouTube and are refreshed by the updater. Teal columns are calculated. Gold columns (Mark, Watched On, Notes) are YOURS and are never overwritten.
A3: =HYPERLINK("#Dashboard!A1","◄ Dashboard")
A5: Open | B5: Status | C5: Mark | D5: Watched On | E5: Published | F5: Channel | G5: Title | H5: Length | I5: Views | J5: Likes | K5: Comments | L5: Notes | M5: Video ID | N5: Channel ID | O5: Published UTC | P5: Day | Q5: Seq | R5: Availability | S5: First Seen | T5: Last Seen | U5: Description | V5: Cal Key | W5: Queue Key
A6: =IF(M6="","",HYPERLINK("https://www.youtube.com/watch?v="&M6,"▶")) | B6: =IF(C6<>"",C6,IF(P6<=IFERROR(INDEX(tblChannels[Watched Through],MATCH(N6,tblChannels[Channel ID],0)),0),"Watched","Unwatched")) | E6: 46297.417 | F6: Popcorn Culture | G6: Top 100 TV Shows! | Popcorn Culture | H6: 0.077893519 | I6: 209 | J6: 16 | K6: 7 | N6: UCHfIbq9thHPC8yrKjAdJgDA | O6: 46297.583 | P6: 46297 | Q6: 3262 | R6: No Video ID yet | U6: In the 356th episode of the Pop, Ben and J discuss victorious sports, nervous tics, evolution of technology, and the NYT 100 Best TV Shows of the 21st Century. NYT 100 Top Shows List - | V6: =IF(AND(P6>=Calendar!$K$2,P6<EDATE(Calendar!$K$2,1),OR(Calendar!$K$4="*",N6=Calendar!$K$4)),P6*100+COUNTIFS($P$6:$P$3267,P6,$Q$6:$Q$3267,"<="&Q6,$N$6:$N$3267,Calendar!$K$4),"") | W6: =IF(AND(B6=Queue!$C$4,OR(Queue!$K$4="*",N6=Queue!$K$4)),Q6,"")
A7: =IF(M7="","",HYPERLINK("https://www.youtube.com/watch?v="&M7,"▶")) | B7: =IF(C7<>"",C7,IF(P7<=IFERROR(INDEX(tblChannels[Watched Through],MATCH(N7,tblChannels[Channel ID],0)),0),"Watched","Unwatched")) | E7: 46295.649 | F7: Super Carlin Brothers | G7: Slughorn’s SECRET Son Revealed | H7: 0.011087963 | I7: 62777 | J7: 1573 | K7: 250 | N7: UCKZo4N0lVPccBkSiuyVh4yg | O7: 46295.815 | P7: 46295 | Q7: 3261 | R7: No Video ID yet | U7: This episode is sponsored by Factor – Head to and use code super50off to get 50% off and 1 free breakfast item per box for 1 year. This episode is sponsored by Raycon – Go to to get 20% off. Today J dives into Horace Slughorn’s memory to find out if he had a secret son hiding in plain sight this whole time. Who was the obsessive love he warns about in potions class? What does it have to do with the Crouch family and was Barty Crouch screaming the truth at us this whole time?! #HarryPotter #supercarlinbrothers | V7: =IF(AND(P7>=Calendar!$K$2,P7<EDATE(Calendar!$K$2,1),OR(Calendar!$K$4="*",N7=Calendar!$K$4)),P7*100+COUNTIFS($P$6:$P$3267,P7,$Q$6:$Q$3267,"<="&Q7,$N$6:$N$3267,Calendar!$K$4),"") | W7: =IF(AND(B7=Queue!$C$4,OR(Queue!$K$4="*",N7=Queue!$K$4)),Q7,"")
A8: =IF(M8="","",HYPERLINK("https://www.youtube.com/watch?v="&M8,"▶")) | B8: =IF(C8<>"",C8,IF(P8<=IFERROR(INDEX(tblChannels[Watched Through],MATCH(N8,tblChannels[Channel ID],0)),0),"Watched","Unwatched")) | E8: 46292.417 | F8: Through The Griffin Door | G8: Chapter 15: The Unbreakable Vow | Half-Blood Prince | H8: 0.076793981 | I8: 41173 | J8: 692 | K8: 303 | N8: UCEscP6ETYXWSSvsNrDHekMQ | O8: 46292.583 | P8: 46292 | Q8: 3260 | R8: No Video ID yet | U8: This episode is sponsored by Shopify – Go to shopify.com/griffin to start your free trial! Taking care of your health just got easier – start here with Zocdoc: Join J and Ben as they dive into Chapter 15 of the Half Blood Prince and discuss mistletoe and snogging, finding the name of Charms, everlasting elixirs, a ridiculous Madame Pince moment, cute Harmione moments, Harry going to the party with Luna, Draco getting caught, strawfangs, and Snape and Malfoy’s secret discussion. 05:45 - Chapter Breakdown 59:48 - Ad Break (Shopify & ZocDoc) 1:02:57 - More Chapter Breakdown 1:43:16 - Closing Thoughts and Review | V8: =IF(AND(P8>=Calendar!$K$2,P8<EDATE(Calendar!$K$2,1),OR(Calendar!$K$4="*",N8=Calendar!$K$4)),P8*100+COUNTIFS($P$6:$P$3267,P8,$Q$6:$Q$3267,"<="&Q8,$N$6:$N$3267,Calendar!$K$4),"") | W8: =IF(AND(B8=Queue!$C$4,OR(Queue!$K$4="*",N8=Queue!$K$4)),Q8,"")
A9: =IF(M9="","",HYPERLINK("https://www.youtube.com/watch?v="&M9,"▶")) | B9: =IF(C9<>"",C9,IF(P9<=IFERROR(INDEX(tblChannels[Watched Through],MATCH(N9,tblChannels[Channel ID],0)),0),"Watched","Unwatched")) | E9: 46290.682 | F9: Super Carlin Brothers | G9: J vs Ben: How Well Do We Know The Boy Who Lived (MAX DIFFICULTY) | H9: 0.034791667 | I9: 102063 | J9: 1791 | K9: 297 | N9: UCKZo4N0lVPccBkSiuyVh4yg | O9: 46290.849 | P9: 46290 | Q9: 3259 | R9: No Video ID yet | U9: This video is sponsored by Proton VPN – go to to get 70% off a two year plan. This video is also sponsored by Faire – Sign up today and get 50% off your first wholesale order, up to $100 at Today J and Ben face off once more to find out who knows more about The Boy Who Lived, The Chosen One: Harry Potter. As the main character, questions about Harry could come from ANYWHERE and span all 7 books - Have our Quiz Masters managed to stump the guys? Special Thanks to these Quiz Masters: Fate3841, Firemon6000, Hermione Baggins, Mercedes, MrTeacher, Kellbell, Peyton Taylor, Elizabeth Potter, Tina's Hotdog Sophie, TrexDog, Julie Sherwood, LifeIsLavely, Crafty Lizard, Teghan Denlinger, Denise, Bradferd, Elfish Princess Hosted by: Kat Stine | V9: =IF(AND(P9>=Calendar!$K$2,P9<EDATE(Calendar!$K$2,1),OR(Calendar!$K$4="*",N9=Calendar!$K$4)),P9*100+COUNTIFS($P$6:$P$3267,P9,$Q$6:$Q$3267,"<="&Q9,$N$6:$N$3267,Calendar!$K$4),"") | W9: =IF(AND(B9=Queue!$C$4,OR(Queue!$K$4="*",N9=Queue!$K$4)),Q9,"")
A10: =IF(M10="","",HYPERLINK("https://www.youtube.com/watch?v="&M10,"▶")) | B10: =IF(C10<>"",C10,IF(P10<=IFERROR(INDEX(tblChannels[Watched Through],MATCH(N10,tblChannels[Channel ID],0)),0),"Watched","Unwatched")) | E10: 46290.417 | F10: Popcorn Culture | G10: Tour in a Podshell | Popcorn Culture | H10: 0.047337963 | I10: 3615 | J10: 90 | K10: 18 | N10: UCHfIbq9thHPC8yrKjAdJgDA | O10: 46290.583 | P10: 46290 | Q10: 3258 | R10: No Video ID yet | U10: In the 355th episode of the Pod, Ben and J discuss all things TOUR: getting locked out of the van, an amazing Boston show, Hartford being AN place, the magic of New York, the race to the finish line and many special moments in between. Lolita - | V10: =IF(AND(P10>=Calendar!$K$2,P10<EDATE(Calendar!$K$2,1),OR(Calendar!$K$4="*",N10=Calendar!$K$4)),P10*100+COUNTIFS($P$6:$P$3267,P10,$Q$6:$Q$3267,"<="&Q10,$N$6:$N$3267,Calendar!$K$4),"") | W10: =IF(AND(B10=Queue!$C$4,OR(Queue!$K$4="*",N10=Queue!$K$4)),Q10,"")
A11: =IF(M11="","",HYPERLINK("https://www.youtube.com/watch?v="&M11,"▶")) | B11: =IF(C11<>"",C11,IF(P11<=IFERROR(INDEX(tblChannels[Watched Through],MATCH(N11,tblChannels[Channel ID],0)),0),"Watched","Unwatched")) | E11: 46289.653 | F11: Popcorn Culture | G11: Mr. Ben's Worst Day Ever | Popcorn Culture | H11: 0.0026273148 | I11: 2235 | J11: 118 | K11: 27 | N11: UCHfIbq9thHPC8yrKjAdJgDA | O11: 46289.82 | P11: 46289 | Q11: 3257 | R11: No Video ID yet | U11: You know that feeling when the universe is determined to make your own life hard for you? Yeah! That. Watch the full episode: Animated by: Isybelle Christley | V11: =IF(AND(P11>=Calendar!$K$2,P11<EDATE(Calendar!$K$2,1),OR(Calendar!$K$4="*",N11=Calendar!$K$4)),P11*100+COUNTIFS($P$6:$P$3267,P11,$Q$6:$Q$3267,"<="&Q11,$N$6:$N$3267,Calendar!$K$4),"") | W11: =IF(AND(B11=Queue!$C$4,OR(Queue!$K$4="*",N11=Queue!$K$4)),Q11,"")
A12: =IF(M12="","",HYPERLINK("https://www.youtube.com/watch?v="&M12,"▶")) | B12: =IF(C12<>"",C12,IF(P12<=IFERROR(INDEX(tblChannels[Watched Through],MATCH(N12,tblChannels[Channel ID],0)),0),"Watched","Unwatched")) | E12: 46288.674 | F12: Super Carlin Brothers | G12: Slughorn’s SECRET Role In Creating Voldemort | H12: 0.011018519 | I12: 188618 | J12: 3039 | K12: 280 | N12: UCKZo4N0lVPccBkSiuyVh4yg | O12: 46288.841 | P12: 46288 | Q12: 3256 | R12: No Video ID yet | U12: This show is sponsored by BetterHelp. Go to to get 10% off your first month. Head to and use code super50off to get 50% off and 1 free breakfast item per box for 1 year. What if Slughorn’s role in Voldemort’s story began long before he explained Horcruxes to Tom Riddle? Today Ben dives into the Wizarding World of Harry Potter and Voldemort’s past. From Merope Gaunt and the Slug Club to Tom’s first connections at Hogwarts, we’re tracing a theory that puts Horace Slughorn at nearly every turning point in Voldemort’s rise. Then there’s a strange run of luck involving Harry, the Half-Blood Prince’s potion book, and Felix Felicis that may have helped bring Voldemort down. Did Slughorn accidentally help create the Dark Lord and give Harry the means to defeat him? Let’s dive on in! | V12: =IF(AND(P12>=Calendar!$K$2,P12<EDATE(Calendar!$K$2,1),OR(Calendar!$K$4="*",N12=Calendar!$K$4)),P12*100+COUNTIFS($P$6:$P$3267,P12,$Q$6:$Q$3267,"<="&Q12,$N$6:$N$3267,Calendar!$K$4),"") | W12: =IF(AND(B12=Queue!$C$4,OR(Queue!$K$4="*",N12=Queue!$K$4)),Q12,"")
A13: =IF(M13="","",HYPERLINK("https://www.youtube.com/watch?v="&M13,"▶")) | B13: =IF(C13<>"",C13,IF(P13<=IFERROR(INDEX(tblChannels[Watched Through],MATCH(N13,tblChannels[Channel ID],0)),0),"Watched","Unwatched")) | E13: 46285.417 | F13: Through The Griffin Door | G13: The Owlery Special Part 5! | H13: 0.054189815 | I13: 25554 | J13: 452 | K13: 122 | N13: UCEscP6ETYXWSSvsNrDHekMQ | O13: 46285.583 | P13: 46285 | Q13: 3255 | R13: No Video ID yet | U13: Join J and Ben as they dive into YOUR QUESTIONS and answer the questions: How EXACTLY does the Unbreakable Vow work? What would have changed if Sirius just picked up Voldy's wand in the Godric's Hollow wreckage? Is Peter Pettigrew actually INCREDIBLY powerful? Do you want to have your questions answered on a future episode of The Owlery? Support us on Patreon: 02:12 - Question 1 27:08 - Question 2 53:40 - Question 3 Edited by :: Ethan Edghill and Isybelle Christley | V13: =IF(AND(P13>=Calendar!$K$2,P13<EDATE(Calendar!$K$2,1),OR(Calendar!$K$4="*",N13=Calendar!$K$4)),P13*100+COUNTIFS($P$6:$P$3267,P13,$Q$6:$Q$3267,"<="&Q13,$N$6:$N$3267,Calendar!$K$4),"") | W13: =IF(AND(B13=Queue!$C$4,OR(Queue!$K$4="*",N13=Queue!$K$4)),Q13,"")
A14: =IF(M14="","",HYPERLINK("https://www.youtube.com/watch?v="&M14,"▶")) | B14: =IF(C14<>"",C14,IF(P14<=IFERROR(INDEX(tblChannels[Watched Through],MATCH(N14,tblChannels[Channel ID],0)),0),"Watched","Unwatched")) | E14: 46283.625 | F14: Super Carlin Brothers | G14: J & Ben VS AI - Harry Potter Trivia | H14: 0.031261574 | I14: 115261 | J14: 2389 | K14: 450 | N14: UCKZo4N0lVPccBkSiuyVh4yg | O14: 46283.792 | P14: 46283 | Q14: 3254 | R14: No Video ID yet | U14: Today J and Ben join forces to take down Artificial Intelligence as they compete with ChatGPT in Harry Potter Trivia. AI might be able to read all 7 books in 3 seconds… but can it remember which kids Voldemort brought to the cave? Which Weasley went through platform 9 ¾ first? Play Along With Us :: | V14: =IF(AND(P14>=Calendar!$K$2,P14<EDATE(Calendar!$K$2,1),OR(Calendar!$K$4="*",N14=Calendar!$K$4)),P14*100+COUNTIFS($P$6:$P$3267,P14,$Q$6:$Q$3267,"<="&Q14,$N$6:$N$3267,Calendar!$K$4),"") | W14: =IF(AND(B14=Queue!$C$4,OR(Queue!$K$4="*",N14=Queue!$K$4)),Q14,"")
A15: =IF(M15="","",HYPERLINK("https://www.youtube.com/watch?v="&M15,"▶")) | B15: =IF(C15<>"",C15,IF(P15<=IFERROR(INDEX(tblChannels[Watched Through],MATCH(N15,tblChannels[Channel ID],0)),0),"Watched","Unwatched")) | E15: 46283.417 | F15: Popcorn Culture | G15: The Roanoke Bracket | Popcorn Culture | H15: 0.050405093 | I15: 3167 | J15: 96 | K15: 22 | N15: UCHfIbq9thHPC8yrKjAdJgDA | O15: 46283.583 | P15: 46283 | Q15: 3253 | R15: No Video ID yet | U15: In the 354th episode of the PopBen and J discuss tour prep, a Roanoke this or that, camaraderie of sports, buying a movie theater, classic Hollywood stories, and CGI Bluey. CGI Bluey Trailer - 2D vs CGI 00:00 - Intro, Tour Prep 01:37 - Improving Roanoke 46:57 - Bringing Back the Oldies 56:40 - CGI Bluey | V15: =IF(AND(P15>=Calendar!$K$2,P15<EDATE(Calendar!$K$2,1),OR(Calendar!$K$4="*",N15=Calendar!$K$4)),P15*100+COUNTIFS($P$6:$P$3267,P15,$Q$6:$Q$3267,"<="&Q15,$N$6:$N$3267,Calendar!$K$4),"") | W15: =IF(AND(B15=Queue!$C$4,OR(Queue!$K$4="*",N15=Queue!$K$4)),Q15,"")
A16: =IF(M16="","",HYPERLINK("https://www.youtube.com/watch?v="&M16,"▶")) | B16: =IF(C16<>"",C16,IF(P16<=IFERROR(INDEX(tblChannels[Watched Through],MATCH(N16,tblChannels[Channel ID],0)),0),"Watched","Unwatched")) | E16: 46281.625 | F16: Super Carlin Brothers | G16: Theories From A Hat: Defending MORE Wild Harry Potter Theories | H16: 0.0271875 | I16: 104475 | J16: 1972 | K16: 409 | N16: UCKZo4N0lVPccBkSiuyVh4yg | O16: 46281.792 | P16: 46281 | Q16: 3252 | R16: No Video ID yet | U16: This show is sponsored by BetterHelp – Go to Today J and Ben are diving into the magical Theory Hat once more to draw and defend your craziest, worst and funniest Harry Potter theories on the fly! Was Snape ACTUALLY in love with James? Did Moody create a Horcrux? Is Felix Felicis just bourbon? Was Hermione secretly in love with Harry?? #HarryPotter #supercarlinbrothers | V16: =IF(AND(P16>=Calendar!$K$2,P16<EDATE(Calendar!$K$2,1),OR(Calendar!$K$4="*",N16=Calendar!$K$4)),P16*100+COUNTIFS($P$6:$P$3267,P16,$Q$6:$Q$3267,"<="&Q16,$N$6:$N$3267,Calendar!$K$4),"") | W16: =IF(AND(B16=Queue!$C$4,OR(Queue!$K$4="*",N16=Queue!$K$4)),Q16,"")
A17: =IF(M17="","",HYPERLINK("https://www.youtube.com/watch?v="&M17,"▶")) | B17: =IF(C17<>"",C17,IF(P17<=IFERROR(INDEX(tblChannels[Watched Through],MATCH(N17,tblChannels[Channel ID],0)),0),"Watched","Unwatched")) | E17: 46278.476 | F17: Through The Griffin Door | G17: Chapter 14: Felix Felicis | Half-Blood Prince | H17: 0.079710648 | I17: 38643 | J17: 813 | K17: 243 | N17: UCEscP6ETYXWSSvsNrDHekMQ | O17: 46278.642 | P17: 46278 | Q17: 3251 | R17: No Video ID yet | U17: This episode is sponsored by Shopify – Go to shopify.com/griffin to start your free trial! Join J and Ben as they dive into Chapter 14 of the Half Blood Prince and discuss “weird mist”, new Voldemort “lore”, Neville crushing herbology, gross plants, the snogging conflict with Ginny, Harry’s placebo plan, Hermione’s fumble, and the beginning of WonWon and LavLav. 5:53- Chapter Breakdown 52:52 - Ad Break (Shopify) 54:33 - More Chapter Breakdown 1:41:11- Closing Thoughts and Review | V17: =IF(AND(P17>=Calendar!$K$2,P17<EDATE(Calendar!$K$2,1),OR(Calendar!$K$4="*",N17=Calendar!$K$4)),P17*100+COUNTIFS($P$6:$P$3267,P17,$Q$6:$Q$3267,"<="&Q17,$N$6:$N$3267,Calendar!$K$4),"") | W17: =IF(AND(B17=Queue!$C$4,OR(Queue!$K$4="*",N17=Queue!$K$4)),Q17,"")
... A202: =IF(M202="","",HYPERLINK("https://www.youtube.com/watch?v="&M202,"▶")) | B202: =IF(C202<>"",C202,IF(P202<=IFERROR(INDEX(tblChannels[Watched Through],MATCH(N202,tblChannels[Channel ID],0)),0),"Watched","Unwatched")) | E202: 45988.542 | F202: Super Carlin Brothers | G202: J vs Ben: Goblet of Fire QUIZ Returns! (THERMAGEDDON 🔥 2.6 Million Scovilles!) | H202: 0.044456019 | I202: 103849 | J202: 3904 | K202: 513 | N202: UCKZo4N0lVPccBkSiuyVh4yg | O202: 45988.75 | P202: 45988 | Q202: 3066 | R202: No Video ID yet | U202: Exclusive $45-off Carver Mat at Promo Code SCB Happy Thanksgiving, everyone! It’s time again for the annual Super Carlin Brothers Goblet of Fire Quiz — but this year we’ve turned the heat ALL the way up. Every wrong answer? Eat a wing covered in over 2.6 million Scovilles of molten thermageddon. Think you know Harry Potter and the Goblet of Fire? Play along and see if YOU can answer these questions before J & Ben melt into puddles of spicy regret.. #HarryPotter #SuperCarlinBrothers #JvsBen Written by: The Quizmasters! Hosted by: Kat Stine, Isybelle Christley and Ethan Edghill 🎟️ Through the Griffin Door LIVE Tour— Southwest 2025 | V202: =IF(AND(P202>=Calendar!$K$2,P202<EDATE(Calendar!$K$2,1),OR(Calendar!$K$4="*",N202=Calendar!$K$4)),P202*100+COUNTIFS($P$6:$P$3267,P202,$Q$6:$Q$3267,"<="&Q202,$N$6:$N$3267,Calendar!$K$4),"") | W202: =IF(AND(B202=Queue!$C$4,OR(Queue!$K$4="*",N202=Queue!$K$4)),Q202,"")
A203: =IF(M203="","",HYPERLINK("https://www.youtube.com/watch?v="&M203,"▶")) | B203: =IF(C203<>"",C203,IF(P203<=IFERROR(INDEX(tblChannels[Watched Through],MATCH(N203,tblChannels[Channel ID],0)),0),"Watched","Unwatched")) | E203: 45987.631 | F203: Super Carlin Brothers | G203: The VEIL Created the Deathly Hallows?! | Harry Potter Theory | H203: 0.011956019 | I203: 91853 | J203: 4079 | K203: 438 | N203: UCKZo4N0lVPccBkSiuyVh4yg | O203: 45987.84 | P203: 45987 | Q203: 3065 | R203: No Video ID yet | V203: =IF(AND(P203>=Calendar!$K$2,P203<EDATE(Calendar!$K$2,1),OR(Calendar!$K$4="*",N203=Calendar!$K$4)),P203*100+COUNTIFS($P$6:$P$3267,P203,$Q$6:$Q$3267,"<="&Q203,$N$6:$N$3267,Calendar!$K$4),"") | W203: =IF(AND(B203=Queue!$C$4,OR(Queue!$K$4="*",N203=Queue!$K$4)),Q203,"")
A204: =IF(M204="","",HYPERLINK("https://www.youtube.com/watch?v="&M204,"▶")) | B204: =IF(C204<>"",C204,IF(P204<=IFERROR(INDEX(tblChannels[Watched Through],MATCH(N204,tblChannels[Channel ID],0)),0),"Watched","Unwatched")) | E204: 45987.625 | F204: Through The Griffin Door | G204: Live in Cleveland - Chapter 13: Detention with Dolores | Order of the Phoenix | H204: 0.05125 | I204: 6440 | J204: 254 | K204: 79 | N204: UCEscP6ETYXWSSvsNrDHekMQ | O204: 45987.833 | P204: 45987 | Q204: 3064 | R204: No Video ID yet | U204: Join J and Ben as they dive BACK into Chapter 13 of Order of the Phoenix LIVE IN CLEVELAND! Harry jumping down EVERYONE'S throats (again), the RIDICULOUS amount of information Draco has compared to Harry, and the literal torture session Umbridge puts him through. | V204: =IF(AND(P204>=Calendar!$K$2,P204<EDATE(Calendar!$K$2,1),OR(Calendar!$K$4="*",N204=Calendar!$K$4)),P204*100+COUNTIFS($P$6:$P$3267,P204,$Q$6:$Q$3267,"<="&Q204,$N$6:$N$3267,Calendar!$K$4),"") | W204: =IF(AND(B204=Queue!$C$4,OR(Queue!$K$4="*",N204=Queue!$K$4)),Q204,"")
A205: =IF(M205="","",HYPERLINK("https://www.youtube.com/watch?v="&M205,"▶")) | B205: =IF(C205<>"",C205,IF(P205<=IFERROR(INDEX(tblChannels[Watched Through],MATCH(N205,tblChannels[Channel ID],0)),0),"Watched","Unwatched")) | E205: 45984.417 | F205: Through The Griffin Door | G205: Chapter 13: Detention with Dolores | Order of the Phoenix | H205: 0.091747685 | I205: 53370 | J205: 1250 | K205: 475 | N205: UCEscP6ETYXWSSvsNrDHekMQ | O205: 45984.626 | P205: 45984 | Q205: 3063 | R205: No Video ID yet | U205: This episode is sponsored by MasterClass – Our listeners get an additional 15% off any annual membership at Join J and Ben as they dive into Chapter 13 of the Order of the Phoenix and discuss Hermione’s perspective, the twins testing on first years, Ronmione moments, better teachers, bowtruckles, Draco knowing about Hagrid, Angelina freaking out about tryouts, the detention from hell and Harry finally finding out about Ron wanting to play Quidditch. Why Neville is ACTUALLY a Samurai - Last Year’s Goblet of FIRE - 09:08 - Chapter Breakdown 1:04:41 - Ad Break (Masterclass) 1:06:16 - More Chapter Breakdown 2:01:01 - Closing Thoughts and Review | V205: =IF(AND(P205>=Calendar!$K$2,P205<EDATE(Calendar!$K$2,1),OR(Calendar!$K$4="*",N205=Calendar!$K$4)),P205*100+COUNTIFS($P$6:$P$3267,P205,$Q$6:$Q$3267,"<="&Q205,$N$6:$N$3267,Calendar!$K$4),"") | W205: =IF(AND(B205=Queue!$C$4,OR(Queue!$K$4="*",N205=Queue!$K$4)),Q205,"")
A206: =IF(M206="","",HYPERLINK("https://www.youtube.com/watch?v="&M206,"▶")) | B206: =IF(C206<>"",C206,IF(P206<=IFERROR(INDEX(tblChannels[Watched Through],MATCH(N206,tblChannels[Channel ID],0)),0),"Watched","Unwatched")) | E206: 45982.685 | F206: Super Carlin Brothers | G206: The Defense Against the Dark Arts Curse EXPLAINED | Harry Potter | H206: 0.010925926 | I206: 85056 | J206: 3669 | K206: 448 | N206: UCKZo4N0lVPccBkSiuyVh4yg | O206: 45982.894 | P206: 45982 | Q206: 3062 | R206: No Video ID yet | U206: This episode is sponsored by BetterHelp – Go to to get 10% off your first month. Today Ben dives into the Wizarding World of Harry Potter to break down one of the most quietly devastating moves Tom Riddle ever made: the infamous Defense Against the Dark Arts Curse. From the snowy night he returned to Hogwarts to hide the diadem, to the ripple effects that shaped entire generations of undertrained witches and wizards, this “petty revenge curse” may actually be Voldemort’s most effective long-term strategy in the entire series. #HarryPotter #SuperCarlinBrothers #JvsBen | V206: =IF(AND(P206>=Calendar!$K$2,P206<EDATE(Calendar!$K$2,1),OR(Calendar!$K$4="*",N206=Calendar!$K$4)),P206*100+COUNTIFS($P$6:$P$3267,P206,$Q$6:$Q$3267,"<="&Q206,$N$6:$N$3267,Calendar!$K$4),"") | W206: =IF(AND(B206=Queue!$C$4,OR(Queue!$K$4="*",N206=Queue!$K$4)),Q206,"")
A207: =IF(M207="","",HYPERLINK("https://www.youtube.com/watch?v="&M207,"▶")) | B207: =IF(C207<>"",C207,IF(P207<=IFERROR(INDEX(tblChannels[Watched Through],MATCH(N207,tblChannels[Channel ID],0)),0),"Watched","Unwatched")) | E207: 45982.417 | F207: Popcorn Culture | G207: Casually Castle Shopping | Popcorn Culture | H207: 0.057604167 | I207: 3375 | J207: 145 | K207: 19 | N207: UCHfIbq9thHPC8yrKjAdJgDA | O207: 45982.625 | P207: 45982 | Q207: 3061 | R207: No Video ID yet | U207: In the 311th episode of the Pop, Ben and J discuss Ben’s new ink, the CRAZY economy of scale in California, iron ore hunting, techno-babble, and rental car woes. The Social Network - | V207: =IF(AND(P207>=Calendar!$K$2,P207<EDATE(Calendar!$K$2,1),OR(Calendar!$K$4="*",N207=Calendar!$K$4)),P207*100+COUNTIFS($P$6:$P$3267,P207,$Q$6:$Q$3267,"<="&Q207,$N$6:$N$3267,Calendar!$K$4),"") | W207: =IF(AND(B207=Queue!$C$4,OR(Queue!$K$4="*",N207=Queue!$K$4)),Q207,"")
A208: =IF(M208="","",HYPERLINK("https://www.youtube.com/watch?v="&M208,"▶")) | B208: =IF(C208<>"",C208,IF(P208<=IFERROR(INDEX(tblChannels[Watched Through],MATCH(N208,tblChannels[Channel ID],0)),0),"Watched","Unwatched")) | E208: 45980.702 | F208: Super Carlin Brothers | G208: J vs Ben: MAX DIFFICULTY Order of the Phoenix Open Book Harry Potter Trivia | H208: 0.035844907 | I208: 82201 | J208: 2839 | K208: 345 | N208: UCKZo4N0lVPccBkSiuyVh4yg | O208: 45980.91 | P208: 45980 | Q208: 3060 | R208: No Video ID yet | U208: Go to now to Get 10 Free Meals + a Free Item for Life! Today J and Ben go head-to-head in a MAX DIFFICULTY Order of the Phoenix Open Book Harry Potter Quiz — and this one is BRUTAL. From Tonks’ broomstick to the Black Family motto, giants, Sturgis Podmore, and MORE… this quiz goes deeper into OOTP than ever before. Think YOU can beat us? Grab your copy of Order of the Phoenix and play along — and don’t forget to submit YOUR questions for next week’s quiz! Special Thanks to our Quiz Masters: Ryan Silveira, Sam Shunpike, magicalmisfires, GooeyChewie, GenKenobi, tinas_hotdog_sophie, Big D aka the Songwriter, Bracelet Liz, Oryan’s Wizard Parts, CJ, MaddstheHatter, Teghan - Denlinger, Bunny, Mia Likes Nougat, Jessica Theirault, Bradferd, Captain Hawk, Drawing Xaos, and Tara Walker. #HarryPotter #SuperCarlinBrothers #JvsBen | V208: =IF(AND(P208>=Calendar!$K$2,P208<EDATE(Calendar!$K$2,1),OR(Calendar!$K$4="*",N208=Calendar!$K$4)),P208*100+COUNTIFS($P$6:$P$3267,P208,$Q$6:$Q$3267,"<="&Q208,$N$6:$N$3267,Calendar!$K$4),"") | W208: =IF(AND(B208=Queue!$C$4,OR(Queue!$K$4="*",N208=Queue!$K$4)),Q208,"")
A209: =IF(M209="","",HYPERLINK("https://www.youtube.com/watch?v="&M209,"▶")) | B209: =IF(C209<>"",C209,IF(P209<=IFERROR(INDEX(tblChannels[Watched Through],MATCH(N209,tblChannels[Channel ID],0)),0),"Watched","Unwatched")) | E209: 45977.417 | F209: Through The Griffin Door | G209: Live in Detroit - Chapter 12: Professor Umbridge | Order Of The Phoenix | H209: 0.054988426 | I209: 10837 | J209: 442 | K209: 117 | N209: UCEscP6ETYXWSSvsNrDHekMQ | O209: 45977.626 | P209: 45977 | Q209: 3059 | R209: No Video ID yet | U209: Join J and Ben as they dive BACK into Chapter 12 of Order of the Phoenix LIVE IN DETROIT! You’re getting the live on Sunday this week cause Ben is ILL. But in this episode J and Ben discuss why Harry is being a real pr… I mean Mimbulus Mimbletonia, Ron’s poor attempts to drop hints about wanting to play quidditch, and how Harry gets just SO much detention… that we don’t even get to read about until next week!! | V209: =IF(AND(P209>=Calendar!$K$2,P209<EDATE(Calendar!$K$2,1),OR(Calendar!$K$4="*",N209=Calendar!$K$4)),P209*100+COUNTIFS($P$6:$P$3267,P209,$Q$6:$Q$3267,"<="&Q209,$N$6:$N$3267,Calendar!$K$4),"") | W209: =IF(AND(B209=Queue!$C$4,OR(Queue!$K$4="*",N209=Queue!$K$4)),Q209,"")
A210: =IF(M210="","",HYPERLINK("https://www.youtube.com/watch?v="&M210,"▶")) | B210: =IF(C210<>"",C210,IF(P210<=IFERROR(INDEX(tblChannels[Watched Through],MATCH(N210,tblChannels[Channel ID],0)),0),"Watched","Unwatched")) | E210: 45976.417 | F210: Super Carlin Brothers | G210: Through the Griffin Door Supercut: Order of the Phoenix Chapters 10-12 | H210: 0.22894676 | I210: 10206 | J210: 206 | K210: 24 | N210: UCKZo4N0lVPccBkSiuyVh4yg | O210: 45976.625 | P210: 45976 | Q210: 3058 | R210: No Video ID yet | U210: 00:00:00 - Chapter 10: Luna Lovegood 1:46:34 - Chapter 11: The Sorting Hat's New Song 3:41:18 - Chapter 12: Professor Umbridge | V210: =IF(AND(P210>=Calendar!$K$2,P210<EDATE(Calendar!$K$2,1),OR(Calendar!$K$4="*",N210=Calendar!$K$4)),P210*100+COUNTIFS($P$6:$P$3267,P210,$Q$6:$Q$3267,"<="&Q210,$N$6:$N$3267,Calendar!$K$4),"") | W210: =IF(AND(B210=Queue!$C$4,OR(Queue!$K$4="*",N210=Queue!$K$4)),Q210,"")
A211: =IF(M211="","",HYPERLINK("https://www.youtube.com/watch?v="&M211,"▶")) | B211: =IF(C211<>"",C211,IF(P211<=IFERROR(INDEX(tblChannels[Watched Through],MATCH(N211,tblChannels[Channel ID],0)),0),"Watched","Unwatched")) | E211: 45975.692 | F211: Super Carlin Brothers | G211: A SCATHING Review of The Order of the Phoenix | Harry Potter | H211: 0.014328704 | I211: 186695 | J211: 6080 | K211: 766 | N211: UCKZo4N0lVPccBkSiuyVh4yg | O211: 45975.9 | P211: 45975 | Q211: 3057 | R211: No Video ID yet | U211: Head on over to to get 15% off! Today J dives into the Wizarding World of Harry Potter to give a SCATHING review of the Order of the Phoenix From losing both Wizarding Wars, to missing obvious clues, to wasting their greatest assets (TONKS!!), to forcing a teenage boy to run an illegal, underground Defense club—this organization fumbles the bag spectacularly at every turn. Let’s dive into the most savage performance review Hogwarts has ever seen. | V211: =IF(AND(P211>=Calendar!$K$2,P211<EDATE(Calendar!$K$2,1),OR(Calendar!$K$4="*",N211=Calendar!$K$4)),P211*100+COUNTIFS($P$6:$P$3267,P211,$Q$6:$Q$3267,"<="&Q211,$N$6:$N$3267,Calendar!$K$4),"") | W211: =IF(AND(B211=Queue!$C$4,OR(Queue!$K$4="*",N211=Queue!$K$4)),Q211,"")
A212: =IF(M212="","",HYPERLINK("https://www.youtube.com/watch?v="&M212,"▶")) | B212: =IF(C212<>"",C212,IF(P212<=IFERROR(INDEX(tblChannels[Watched Through],MATCH(N212,tblChannels[Channel ID],0)),0),"Watched","Unwatched")) | E212: 45975.417 | F212: Popcorn Culture | G212: "Yes, And..." | Popcorn Culture | H212: 0.046064815 | I212: 2939 | J212: 138 | K212: 15 | N212: UCHfIbq9thHPC8yrKjAdJgDA | O212: 45975.625 | P212: 45975 | Q212: 3056 | R212: No Video ID yet | U212: In the 310th episode of the Pop, Ben and J discuss “yes, and” improv, a new coined phrase, “A-Pop”, 67, music trivia, wall art, and tattoo complexities. Fool Me Once… - Bluey - KPop Demon Hunters - Spider-Man: Into the Spider-Verse - Klaus - Talladega Nights: The Ballad of Ricky Bobby - Will Gay - 00:00 - Intro, Hostmanship 06:32 - Yes, And-ing 11:51 - A-Pop 44:42 - Wall Art | V212: =IF(AND(P212>=Calendar!$K$2,P212<EDATE(Calendar!$K$2,1),OR(Calendar!$K$4="*",N212=Calendar!$K$4)),P212*100+COUNTIFS($P$6:$P$3267,P212,$Q$6:$Q$3267,"<="&Q212,$N$6:$N$3267,Calendar!$K$4),"") | W212: =IF(AND(B212=Queue!$C$4,OR(Queue!$K$4="*",N212=Queue!$K$4)),Q212,"")
A213: =IF(M213="","",HYPERLINK("https://www.youtube.com/watch?v="&M213,"▶")) | B213: =IF(C213<>"",C213,IF(P213<=IFERROR(INDEX(tblChannels[Watched Through],MATCH(N213,tblChannels[Channel ID],0)),0),"Watched","Unwatched")) | E213: 45973.719 | F213: Super Carlin Brothers | G213: The Invisibility Cloak’s SECRET Power | Harry Potter Theory | H213: 0.012974537 | I213: 132393 | J213: 5518 | K213: 612 | N213: UCKZo4N0lVPccBkSiuyVh4yg | O213: 45973.928 | P213: 45973 | Q213: 3055 | R213: No Video ID yet | U213: This episode is sponsored by BetterHelp. Go to to get 10% off your first month. Go to to sign up for your $1-per-month trial period. What makes Harry Potter’s Invisibility Cloak truly special? Sure, it’s one of the legendary Deathly Hallows — indestructible, eternal, and able to render its wearer perfectly invisible. But Dumbledore tells Harry that it only ever worked fully for him, its rightful master. So what’s the secret power hidden inside the Cloak? In this video, J dives deep into the theory that the Cloak’s magic isn’t about invisibility at all — it’s about protection. From Moody’s enchanted eye to the Marauder’s Map and even Nagini at Godric’s Hollow, every moment the Cloak “fails” actually proves it’s doing something more powerful… 😉 Because sometimes, to stay hidden… you have to be seen. | V213: =IF(AND(P213>=Calendar!$K$2,P213<EDATE(Calendar!$K$2,1),OR(Calendar!$K$4="*",N213=Calendar!$K$4)),P213*100+COUNTIFS($P$6:$P$3267,P213,$Q$6:$Q$3267,"<="&Q213,$N$6:$N$3267,Calendar!$K$4),"") | W213: =IF(AND(B213=Queue!$C$4,OR(Queue!$K$4="*",N213=Queue!$K$4)),Q213,"")
A214: =IF(M214="","",HYPERLINK("https://www.youtube.com/watch?v="&M214,"▶")) | B214: =IF(C214<>"",C214,IF(P214<=IFERROR(INDEX(tblChannels[Watched Through],MATCH(N214,tblChannels[Channel ID],0)),0),"Watched","Unwatched")) | E214: 45973.213 | F214: Super Carlin Gaming | G214: BEN PLAYS DIABLO 2 FOR NO REASON ON A TUESDAY DIABLO 2SDAY ANYONE? | H214: 0.058576389 | I214: 1344 | J214: 73 | K214: 13 | N214: UCor_9jRnNNZVzTuQ92PKsaQ | O214: 45973.421 | P214: 45973 | Q214: 3054 | R214: No Video ID yet | U214: Hey. The gaming channel is getting a reboot. We have a new computer and stuff and we're working out the kinks. So come say hello. ask questions. be feisty. but not too feisty. look you're already overthinking it. just be yourself. wow. | V214: =IF(AND(P214>=Calendar!$K$2,P214<EDATE(Calendar!$K$2,1),OR(Calendar!$K$4="*",N214=Calendar!$K$4)),P214*100+COUNTIFS($P$6:$P$3267,P214,$Q$6:$Q$3267,"<="&Q214,$N$6:$N$3267,Calendar!$K$4),"") | W214: =IF(AND(B214=Queue!$C$4,OR(Queue!$K$4="*",N214=Queue!$K$4)),Q214,"")
A215: =IF(M215="","",HYPERLINK("https://www.youtube.com/watch?v="&M215,"▶")) | B215: =IF(C215<>"",C215,IF(P215<=IFERROR(INDEX(tblChannels[Watched Through],MATCH(N215,tblChannels[Channel ID],0)),0),"Watched","Unwatched")) | E215: 45970.417 | F215: Through The Griffin Door | G215: Chapter 12: Professor Umbridge | Order of the Phoenix | H215: 0.075266204 | I215: 49505 | J215: 1243 | K215: 462 | N215: UCEscP6ETYXWSSvsNrDHekMQ | O215: 45970.625 | P215: 45970 | Q215: 3053 | R215: No Video ID yet | U215: Join J and Ben as they dive into Chapter 12 of the Order of the Phoenix and discuss Dean being Switzerland, Fred and George’s flyer, Ron’s subtle Quidditch hints, OWLs, Snape still being a bad Potions teacher, Divination class, and every infuriating moment of Umbridge’s class. 06:14 - Chapter Breakdown 1:39:46 - Closing Thoughts and Review | V215: =IF(AND(P215>=Calendar!$K$2,P215<EDATE(Calendar!$K$2,1),OR(Calendar!$K$4="*",N215=Calendar!$K$4)),P215*100+COUNTIFS($P$6:$P$3267,P215,$Q$6:$Q$3267,"<="&Q215,$N$6:$N$3267,Calendar!$K$4),"") | W215: =IF(AND(B215=Queue!$C$4,OR(Queue!$K$4="*",N215=Queue!$K$4)),Q215,"")
... A217: =IF(M217="","",HYPERLINK("https://www.youtube.com/watch?v="&M217,"▶")) | B217: =IF(C217<>"",C217,IF(P217<=IFERROR(INDEX(tblChannels[Watched Through],MATCH(N217,tblChannels[Channel ID],0)),0),"Watched","Unwatched")) | E217: 45968.66 | F217: Through The Griffin Door | G217: Live In Chicago - Chapter 11: The Sorting Hat's New Song | Order of the Phoenix | H217: 0.052638889 | I217: 7417 | J217: 320 | K217: 58 | N217: UCEscP6ETYXWSSvsNrDHekMQ | O217: 45968.868 | P217: 45968 | Q217: 3051 | R217: No Video ID yet | U217: Join J and Ben as they dive BACK into Chapter 11 of Order of the Phoenix LIVE IN CHICAGO! and honestly you just have to watch this one because J sings THE ENTIRE SONG and it is worth the price of admission | V217: =IF(AND(P217>=Calendar!$K$2,P217<EDATE(Calendar!$K$2,1),OR(Calendar!$K$4="*",N217=Calendar!$K$4)),P217*100+COUNTIFS($P$6:$P$3267,P217,$Q$6:$Q$3267,"<="&Q217,$N$6:$N$3267,Calendar!$K$4),"") | W217: =IF(AND(B217=Queue!$C$4,OR(Queue!$K$4="*",N217=Queue!$K$4)),Q217,"")
A218: =IF(M218="","",HYPERLINK("https://www.youtube.com/watch?v="&M218,"▶")) | B218: =IF(C218<>"",C218,IF(P218<=IFERROR(INDEX(tblChannels[Watched Through],MATCH(N218,tblChannels[Channel ID],0)),0),"Watched","Unwatched")) | E218: 45968.541 | F218: Popcorn Culture | G218: ARE WE LIVE?! | Popcorn Culture | H218: 0.046238426 | I218: 2453 | J218: 120 | K218: 16 | N218: UCHfIbq9thHPC8yrKjAdJgDA | O218: 45968.749 | P218: 45968 | Q218: 3050 | R218: No Video ID yet | V218: =IF(AND(P218>=Calendar!$K$2,P218<EDATE(Calendar!$K$2,1),OR(Calendar!$K$4="*",N218=Calendar!$K$4)),P218*100+COUNTIFS($P$6:$P$3267,P218,$Q$6:$Q$3267,"<="&Q218,$N$6:$N$3267,Calendar!$K$4),"") | W218: =IF(AND(B218=Queue!$C$4,OR(Queue!$K$4="*",N218=Queue!$K$4)),Q218,"")
A219: =IF(M219="","",HYPERLINK("https://www.youtube.com/watch?v="&M219,"▶")) | B219: =IF(C219<>"",C219,IF(P219<=IFERROR(INDEX(tblChannels[Watched Through],MATCH(N219,tblChannels[Channel ID],0)),0),"Watched","Unwatched")) | E219: 45968.484 | F219: Popcorn Culture | G219: POP Question and A with Benjamin and J - 11/07/2025 - GETCHER TAQUITOS | H219: 0.0011921296 | I219: 452 | J219: 22 | K219: 3 | N219: UCHfIbq9thHPC8yrKjAdJgDA | O219: 45968.692 | P219: 45968 | Q219: 3049 | R219: No Video ID yet | U219: Hello Patrons! As ever thank you for your support! Excited to chat with everyone and answer all the questions! | V219: =IF(AND(P219>=Calendar!$K$2,P219<EDATE(Calendar!$K$2,1),OR(Calendar!$K$4="*",N219=Calendar!$K$4)),P219*100+COUNTIFS($P$6:$P$3267,P219,$Q$6:$Q$3267,"<="&Q219,$N$6:$N$3267,Calendar!$K$4),"") | W219: =IF(AND(B219=Queue!$C$4,OR(Queue!$K$4="*",N219=Queue!$K$4)),Q219,"")
A220: =IF(M220="","",HYPERLINK("https://www.youtube.com/watch?v="&M220,"▶")) | B220: =IF(C220<>"",C220,IF(P220<=IFERROR(INDEX(tblChannels[Watched Through],MATCH(N220,tblChannels[Channel ID],0)),0),"Watched","Unwatched")) | E220: 45968.417 | F220: Popcorn Culture | G220: The BIGGEST NYC Marathon! | Popcorn Culture | H220: 0.043969907 | I220: 2537 | J220: 125 | K220: 12 | N220: UCHfIbq9thHPC8yrKjAdJgDA | O220: 45968.625 | P220: 45968 | Q220: 3048 | R220: No Video ID yet | U220: In the 309th episode of the Pop, Ben and J discuss more travel woes, carboloading, The Great Gatsby, THE Marathon, cheering sprints, and future triathlons. Without Limits - Go Pin Pro HQ - The Great Gatsby - | V220: =IF(AND(P220>=Calendar!$K$2,P220<EDATE(Calendar!$K$2,1),OR(Calendar!$K$4="*",N220=Calendar!$K$4)),P220*100+COUNTIFS($P$6:$P$3267,P220,$Q$6:$Q$3267,"<="&Q220,$N$6:$N$3267,Calendar!$K$4),"") | W220: =IF(AND(B220=Queue!$C$4,OR(Queue!$K$4="*",N220=Queue!$K$4)),Q220,"")
A221: =IF(M221="","",HYPERLINK("https://www.youtube.com/watch?v="&M221,"▶")) | B221: =IF(C221<>"",C221,IF(P221<=IFERROR(INDEX(tblChannels[Watched Through],MATCH(N221,tblChannels[Channel ID],0)),0),"Watched","Unwatched")) | E221: 45966.683 | F221: Super Carlin Brothers | G221: Was Voldemort Planning to Eradicate ALL Wizards? | Harry Potter Theory | H221: 0.010601852 | I221: 101211 | J221: 4529 | K221: 558 | N221: UCKZo4N0lVPccBkSiuyVh4yg | O221: 45966.891 | P221: 45966 | Q221: 3047 | R221: No Video ID yet | U221: This episode is sponsored by BetterHelp – Go to to get 10% off your first month. Was Voldemort’s obsession with “purebloods” and immortality a front for something even darker? From the Gaunt family’s collapse to the twisted irony of his own half-blood heritage, this theory explores how Voldemort’s perfect world may have ended in the extinction of wizardkind itself. Join us as we explore what might’ve happened if the Boy Who Lived… hadn’t. | V221: =IF(AND(P221>=Calendar!$K$2,P221<EDATE(Calendar!$K$2,1),OR(Calendar!$K$4="*",N221=Calendar!$K$4)),P221*100+COUNTIFS($P$6:$P$3267,P221,$Q$6:$Q$3267,"<="&Q221,$N$6:$N$3267,Calendar!$K$4),"") | W221: =IF(AND(B221=Queue!$C$4,OR(Queue!$K$4="*",N221=Queue!$K$4)),Q221,"")
A222: =IF(M222="","",HYPERLINK("https://www.youtube.com/watch?v="&M222,"▶")) | B222: =IF(C222<>"",C222,IF(P222<=IFERROR(INDEX(tblChannels[Watched Through],MATCH(N222,tblChannels[Channel ID],0)),0),"Watched","Unwatched")) | E222: 45966.458 | F222: Through The Griffin Door | G222: THROUGH THE GRIFFIN TOUR - SOUTHWEST | H222: 0.0017476852 | I222: 2476 | J222: 158 | K222: 38 | N222: UCEscP6ETYXWSSvsNrDHekMQ | O222: 45966.667 | P222: 45966 | Q222: 3046 | R222: No Video ID yet | U222: Calling All Griffin Doorks! We are so excited to announce that we will be continuing the Through the Griffin TOUR in the Southwest this March! Tickets go on sale THIS FRIDAY, November 7th at 10:00am LOCAL TIME. You can find the links to each location here on our website! Denver, CO - 03/07 Salt Lake City, UT - 03/09 Las Vegas, NV - 03/11 Phoenix, AZ - 03/12 Houston, TX - 03/14 Dallas, TX - 03/15 VIP tickets will be available yet again for this tour as well for an additional $50! These will include a VIP meet and greet with J and Ben, a signed tour poster and early/premium seating. Each of the websites does their VIP ticket add ons differently so be sure to pay attention to how to add that before you check out! Again, you can get your tickets here: on Friday, November 7th at 10:00am LOCAL TIME. We can’t wait to see you in real life, brother! Denver, CO - 03/07/2026: Salt Lake City, UT - 03/09/2026: Las Vegas, NV - 03/11/2026: Phoenix, AZ - 03/12/2026: Houston, TX - 03/14/2026: Dallas, TX - 03/15/2026: | V222: =IF(AND(P222>=Calendar!$K$2,P222<EDATE(Calendar!$K$2,1),OR(Calendar!$K$4="*",N222=Calendar!$K$4)),P222*100+COUNTIFS($P$6:$P$3267,P222,$Q$6:$Q$3267,"<="&Q222,$N$6:$N$3267,Calendar!$K$4),"") | W222: =IF(AND(B222=Queue!$C$4,OR(Queue!$K$4="*",N222=Queue!$K$4)),Q222,"")
A223: =IF(M223="","",HYPERLINK("https://www.youtube.com/watch?v="&M223,"▶")) | B223: =IF(C223<>"",C223,IF(P223<=IFERROR(INDEX(tblChannels[Watched Through],MATCH(N223,tblChannels[Channel ID],0)),0),"Watched","Unwatched")) | E223: 45966.458 | F223: Super Carlin Brothers | G223: THROUGH THE GRIFFIN TOUR - SOUTHWEST | H223: 0.00085648148 | I223: 3913 | J223: 204 | K223: 70 | N223: UCKZo4N0lVPccBkSiuyVh4yg | O223: 45966.667 | P223: 45966 | Q223: 3045 | R223: No Video ID yet | U223: Calling All Griffin Doorks! We are so excited to announce that we will be continuing the Through the Griffin TOUR in the Southwest this March! Tickets go on sale THIS FRIDAY, November 7th at 10:00am LOCAL TIME. You can find the links to each location here on our website! Denver, CO - 03/07 Salt Lake City, UT - 03/09 Las Vegas, NV - 03/11 Phoenix, AZ - 03/12 Houston, TX - 03/14 Dallas, TX - 03/15 VIP tickets will be available yet again for this tour as well for an additional $50! These will include a VIP meet and greet with J and Ben, a signed tour poster and early/premium seating. Each of the websites does their VIP ticket add ons differently so be sure to pay attention to how to add that before you check out! Again, you can get your tickets here: on Friday, November 7th at 10:00am LOCAL TIME. We can’t wait to see you in real life, brother! Denver, CO - 03/07/2026: Salt Lake City, UT - 03/09/2026: Las Vegas, NV - 03/11/2026: Phoenix, AZ - 03/12/2026: Houston, TX - 03/14/2026: Dallas, TX - 03/15/2026: | V223: =IF(AND(P223>=Calendar!$K$2,P223<EDATE(Calendar!$K$2,1),OR(Calendar!$K$4="*",N223=Calendar!$K$4)),P223*100+COUNTIFS($P$6:$P$3267,P223,$Q$6:$Q$3267,"<="&Q223,$N$6:$N$3267,Calendar!$K$4),"") | W223: =IF(AND(B223=Queue!$C$4,OR(Queue!$K$4="*",N223=Queue!$K$4)),Q223,"")
A224: =IF(M224="","",HYPERLINK("https://www.youtube.com/watch?v="&M224,"▶")) | B224: =IF(C224<>"",C224,IF(P224<=IFERROR(INDEX(tblChannels[Watched Through],MATCH(N224,tblChannels[Channel ID],0)),0),"Watched","Unwatched")) | E224: 45963.417 | F224: Through The Griffin Door | G224: Chapter 11: The Sorting Hat’s New Song | Order of the Phoenix | H224: 0.080462963 | I224: 49858 | J224: 1232 | K224: 384 | N224: UCEscP6ETYXWSSvsNrDHekMQ | O224: 45963.626 | P224: 45963 | Q224: 3044 | R224: No Video ID yet | U224: Join J and Ben as they dive into Chapter 11 of the Order of the Phoenix and discuss Luna’s thoughts on Hagrid, students whispering about Harry, Hagrid’s vegetarianism, the Hat’s song, the Founders, Umbridge’s speech and the ramifications of it. 07:25 - Chapter Breakdown 1:09:58 - Ad Break (Shopify) 1:11:23 - More Chapter Breakdown 1:41:47 - Closing Thoughts and Review | V224: =IF(AND(P224>=Calendar!$K$2,P224<EDATE(Calendar!$K$2,1),OR(Calendar!$K$4="*",N224=Calendar!$K$4)),P224*100+COUNTIFS($P$6:$P$3267,P224,$Q$6:$Q$3267,"<="&Q224,$N$6:$N$3267,Calendar!$K$4),"") | W224: =IF(AND(B224=Queue!$C$4,OR(Queue!$K$4="*",N224=Queue!$K$4)),Q224,"")
A225: =IF(M225="","",HYPERLINK("https://www.youtube.com/watch?v="&M225,"▶")) | B225: =IF(C225<>"",C225,IF(P225<=IFERROR(INDEX(tblChannels[Watched Through],MATCH(N225,tblChannels[Channel ID],0)),0),"Watched","Unwatched")) | E225: 45961.674 | F225: Super Carlin Brothers | G225: Why Dumbledore REALLY Says He See Socks In The Mirror | Harry Potter Theory | H225: 0.011087963 | I225: 125461 | J225: 5312 | K225: 568 | N225: UCKZo4N0lVPccBkSiuyVh4yg | O225: 45961.84 | P225: 45961 | Q225: 3043 | R225: No Video ID yet | U225: Today J dives into the Wizarding World of Harry Potter to reveal WHY Dumbledore claims to see himself holding socks in the Mirror of Erised. Go to and use code super50off to get 50% off your first box, plus Free Breakfast for 1 Year. It goes way deeper than you think. Today we break down the symbolism of socks across the entire Harry Potter series — from Dobby’s freedom to Hermione’s knitted S.P.E.W. gifts — and reveal how Dumbledore’s “joke” about socks actually hides his most profound regret: the family he lost and the freedom he never found. Go Check out Katy for more fun HP thoughts! | V225: =IF(AND(P225>=Calendar!$K$2,P225<EDATE(Calendar!$K$2,1),OR(Calendar!$K$4="*",N225=Calendar!$K$4)),P225*100+COUNTIFS($P$6:$P$3267,P225,$Q$6:$Q$3267,"<="&Q225,$N$6:$N$3267,Calendar!$K$4),"") | W225: =IF(AND(B225=Queue!$C$4,OR(Queue!$K$4="*",N225=Queue!$K$4)),Q225,"")
A226: =IF(M226="","",HYPERLINK("https://www.youtube.com/watch?v="&M226,"▶")) | B226: =IF(C226<>"",C226,IF(P226<=IFERROR(INDEX(tblChannels[Watched Through],MATCH(N226,tblChannels[Channel ID],0)),0),"Watched","Unwatched")) | E226: 45961.417 | F226: Popcorn Culture | G226: Luke’s Toy Empathy | Popcorn Culture | H226: 0.044583333 | I226: 2770 | J226: 153 | K226: 23 | N226: UCHfIbq9thHPC8yrKjAdJgDA | O226: 45961.583 | P226: 45961 | Q226: 3042 | R226: No Video ID yet | U226: In the 308th episode of the Pop, Ben and J discuss swimming in cold weather, BIG CHAP, KPop, Luke’s empathy, the Reverse Golden Rule, and analogies. KPop Demon Hunters - BLACKPINK - Elemental - Max Verstappen Song - Green Day - Nobody Wants This - BIG CHAP Chapless Benjamin 00:00 - Intro, Swimming 16:24 - An Embarrassing Story 28:33 - Luke’s Empathy | V226: =IF(AND(P226>=Calendar!$K$2,P226<EDATE(Calendar!$K$2,1),OR(Calendar!$K$4="*",N226=Calendar!$K$4)),P226*100+COUNTIFS($P$6:$P$3267,P226,$Q$6:$Q$3267,"<="&Q226,$N$6:$N$3267,Calendar!$K$4),"") | W226: =IF(AND(B226=Queue!$C$4,OR(Queue!$K$4="*",N226=Queue!$K$4)),Q226,"")
...

Sheet Queue
B2: Watch Queue
C3: Show | D3: Channel | E3: Order
B4: =HYPERLINK("#Dashboard!A1","◄ Dashboard") | C4: Unwatched | D4: All channels | E4: Oldest first | K4: =IF($D$4="All channels","*",IFERROR(INDEX(tblChannels[Channel ID],MATCH($D$4,tblChannels[Display Name],0)),"none"))
B5: =COUNT(tblVideos[Queue Key])&" videos match · "&IF(ROUND((SUMIFS(tblVideos[Length],tblVideos[Queue Key],">0"))*1440,0)<60,ROUND((SUMIFS(tblVideos[Length],tblVideos[Queue Key],">0"))*1440,0)&" m",IF(MOD(ROUND((SUMIFS(tblVideos[Length],tblVideos[Queue Key],">0"))*1440,0),60)=0,INT(ROUND((SUMIFS(tblVideos[Length],tblVideos[Queue Key],">0"))*1440,0)/60)&" h",INT(ROUND((SUMIFS(tblVideos[Length],tblVideos[Queue Key],">0"))*1440,0)/60)&" h "&MOD(ROUND((SUMIFS(tblVideos[Length],tblVideos[Queue Key],">0"))*1440,0),60)&" m"))&" of runtime"
B6: Your next videos. Click a title to open it on YouTube; mark it watched in the Library.
B7: # | C7: Published | D7: Channel | E7: Title | F7: Length | G7: Status
B8: =IF($I8="","",1) | C8: =IF($I8="","",INDEX(tblVideos[Day],$I8)) | D8: =IF($I8="","",INDEX(tblVideos[Channel],$I8)) | E8: =IF($I8="","",IF(INDEX(tblVideos[Video ID],$I8)="",INDEX(tblVideos[Title],$I8),HYPERLINK("https://www.youtube.com/watch?v="&INDEX(tblVideos[Video ID],$I8),INDEX(tblVideos[Title],$I8)))) | F8: =IF($I8="","",INDEX(tblVideos[Length],$I8)) | G8: =IF($I8="","",INDEX(tblVideos[Status],$I8)) | I8: =IFERROR(MATCH(IF($E$4="Newest first",LARGE(tblVideos[Queue Key],1),SMALL(tblVideos[Queue Key],1)),tblVideos[Seq],0),"")
B9: =IF($I9="","",2) | C9: =IF($I9="","",INDEX(tblVideos[Day],$I9)) | D9: =IF($I9="","",INDEX(tblVideos[Channel],$I9)) | E9: =IF($I9="","",IF(INDEX(tblVideos[Video ID],$I9)="",INDEX(tblVideos[Title],$I9),HYPERLINK("https://www.youtube.com/watch?v="&INDEX(tblVideos[Video ID],$I9),INDEX(tblVideos[Title],$I9)))) | F9: =IF($I9="","",INDEX(tblVideos[Length],$I9)) | G9: =IF($I9="","",INDEX(tblVideos[Status],$I9)) | I9: =IFERROR(MATCH(IF($E$4="Newest first",LARGE(tblVideos[Queue Key],2),SMALL(tblVideos[Queue Key],2)),tblVideos[Seq],0),"")
B10: =IF($I10="","",3) | C10: =IF($I10="","",INDEX(tblVideos[Day],$I10)) | D10: =IF($I10="","",INDEX(tblVideos[Channel],$I10)) | E10: =IF($I10="","",IF(INDEX(tblVideos[Video ID],$I10)="",INDEX(tblVideos[Title],$I10),HYPERLINK("https://www.youtube.com/watch?v="&INDEX(tblVideos[Video ID],$I10),INDEX(tblVideos[Title],$I10)))) | F10: =IF($I10="","",INDEX(tblVideos[Length],$I10)) | G10: =IF($I10="","",INDEX(tblVideos[Status],$I10)) | I10: =IFERROR(MATCH(IF($E$4="Newest first",LARGE(tblVideos[Queue Key],3),SMALL(tblVideos[Queue Key],3)),tblVideos[Seq],0),"")
B11: =IF($I11="","",4) | C11: =IF($I11="","",INDEX(tblVideos[Day],$I11)) | D11: =IF($I11="","",INDEX(tblVideos[Channel],$I11)) | E11: =IF($I11="","",IF(INDEX(tblVideos[Video ID],$I11)="",INDEX(tblVideos[Title],$I11),HYPERLINK("https://www.youtube.com/watch?v="&INDEX(tblVideos[Video ID],$I11),INDEX(tblVideos[Title],$I11)))) | F11: =IF($I11="","",INDEX(tblVideos[Length],$I11)) | G11: =IF($I11="","",INDEX(tblVideos[Status],$I11)) | I11: =IFERROR(MATCH(IF($E$4="Newest first",LARGE(tblVideos[Queue Key],4),SMALL(tblVideos[Queue Key],4)),tblVideos[Seq],0),"")
B12: =IF($I12="","",5) | C12: =IF($I12="","",INDEX(tblVideos[Day],$I12)) | D12: =IF($I12="","",INDEX(tblVideos[Channel],$I12)) | E12: =IF($I12="","",IF(INDEX(tblVideos[Video ID],$I12)="",INDEX(tblVideos[Title],$I12),HYPERLINK("https://www.youtube.com/watch?v="&INDEX(tblVideos[Video ID],$I12),INDEX(tblVideos[Title],$I12)))) | F12: =IF($I12="","",INDEX(tblVideos[Length],$I12)) | G12: =IF($I12="","",INDEX(tblVideos[Status],$I12)) | I12: =IFERROR(MATCH(IF($E$4="Newest first",LARGE(tblVideos[Queue Key],5),SMALL(tblVideos[Queue Key],5)),tblVideos[Seq],0),"")
B13: =IF($I13="","",6) | C13: =IF($I13="","",INDEX(tblVideos[Day],$I13)) | D13: =IF($I13="","",INDEX(tblVideos[Channel],$I13)) | E13: =IF($I13="","",IF(INDEX(tblVideos[Video ID],$I13)="",INDEX(tblVideos[Title],$I13),HYPERLINK("https://www.youtube.com/watch?v="&INDEX(tblVideos[Video ID],$I13),INDEX(tblVideos[Title],$I13)))) | F13: =IF($I13="","",INDEX(tblVideos[Length],$I13)) | G13: =IF($I13="","",INDEX(tblVideos[Status],$I13)) | I13: =IFERROR(MATCH(IF($E$4="Newest first",LARGE(tblVideos[Queue Key],6),SMALL(tblVideos[Queue Key],6)),tblVideos[Seq],0),"")
B14: =IF($I14="","",7) | C14: =IF($I14="","",INDEX(tblVideos[Day],$I14)) | D14: =IF($I14="","",INDEX(tblVideos[Channel],$I14)) | E14: =IF($I14="","",IF(INDEX(tblVideos[Video ID],$I14)="",INDEX(tblVideos[Title],$I14),HYPERLINK("https://www.youtube.com/watch?v="&INDEX(tblVideos[Video ID],$I14),INDEX(tblVideos[Title],$I14)))) | F14: =IF($I14="","",INDEX(tblVideos[Length],$I14)) | G14: =IF($I14="","",INDEX(tblVideos[Status],$I14)) | I14: =IFERROR(MATCH(IF($E$4="Newest first",LARGE(tblVideos[Queue Key],7),SMALL(tblVideos[Queue Key],7)),tblVideos[Seq],0),"")
B15: =IF($I15="","",8) | C15: =IF($I15="","",INDEX(tblVideos[Day],$I15)) | D15: =IF($I15="","",INDEX(tblVideos[Channel],$I15)) | E15: =IF($I15="","",IF(INDEX(tblVideos[Video ID],$I15)="",INDEX(tblVideos[Title],$I15),HYPERLINK("https://www.youtube.com/watch?v="&INDEX(tblVideos[Video ID],$I15),INDEX(tblVideos[Title],$I15)))) | F15: =IF($I15="","",INDEX(tblVideos[Length],$I15)) | G15: =IF($I15="","",INDEX(tblVideos[Status],$I15)) | I15: =IFERROR(MATCH(IF($E$4="Newest first",LARGE(tblVideos[Queue Key],8),SMALL(tblVideos[Queue Key],8)),tblVideos[Seq],0),"")
B16: =IF($I16="","",9) | C16: =IF($I16="","",INDEX(tblVideos[Day],$I16)) | D16: =IF($I16="","",INDEX(tblVideos[Channel],$I16)) | E16: =IF($I16="","",IF(INDEX(tblVideos[Video ID],$I16)="",INDEX(tblVideos[Title],$I16),HYPERLINK("https://www.youtube.com/watch?v="&INDEX(tblVideos[Video ID],$I16),INDEX(tblVideos[Title],$I16)))) | F16: =IF($I16="","",INDEX(tblVideos[Length],$I16)) | G16: =IF($I16="","",INDEX(tblVideos[Status],$I16)) | I16: =IFERROR(MATCH(IF($E$4="Newest first",LARGE(tblVideos[Queue Key],9),SMALL(tblVideos[Queue Key],9)),tblVideos[Seq],0),"")
